<?xml version="1.0" encoding="utf-8"?>
<!-- =================================================================================== -->
<!-- |    This document was autogenerated by xacro from test_reach5mini.urdf.xacro     | -->
<!-- |    EDITING THIS FILE BY HAND IS NOT RECOMMENDED                                 | -->
<!-- |    Unless you're Hannah Kolano or Scott Chow  -->
<!-- =================================================================================== -->
<!-- when doing STL -> OBJ conversion, use this to keep origins: https://blender.stackexchange.com/questions/26451/how-to-move-a-complex-object-to-the-origin-without-destroying-it -->
<robot name="uvms_alpha_seabotix">
  <!-- ======================================= -->
  <!-- - - - - - - - MATERIALS - - - - - - - - -->
  <!-- ======================================= -->
    <material name="alpha_black">
      <color rgba="0.6 0.6 0.6 1"/>
    </material>
    <material name="green_v">
      <color rgba="0.5 0.9 0.3 1"/>
    </material>
    <material name="black">
      <color rgba="0 0 0 1"/>
    </material>
    <material name="black_v">
      <color rgba="0 0 0 1"/>
    </material>
    <material name="blue_v">
      <color rgba="0.2 0.4 0.6 1"/>
    </material>
    <material name="orange_v">
      <color rgba="1 .4 0 1"/>
    </material>
    <material name="grey_v">
      <color rgba=".3 .3 .3 1"/>
    </material>
    <material name="red_v">
      <color rgba="1 0 0 1"/>
    </material>

  <!-- ======================================= -->
  <!--               WORLD LINKS               -->
  <!-- ======================================= -->

  <!-- ======================================= -->
  <!--             VEHICLE LINKS               -->
  <!-- ======================================= -->
  <link name="vehicle_base_link">
    <visual>
      <geometry>
        <box size="0.5 0.4 0.15"/>
      </geometry>
      <material name="green_v"/>
      <!-- <origin rpy="1.57075 0 0" xyz="0 0 0"/> -->
      <!-- <origin rpy="0 0 0" xyz="0 0 0"/> -->
      <!-- <material name="alpha_black"/> -->
    </visual>
    <!-- Actual *not added* -->
    <!-- <inertial> -->
      <!-- <mass value="22.2"/>  -->
      <!-- Assume COM is 6cm below the center of the green box (13.5cm from top of vehicle) -->
      <!-- <origin xyz="0.0 0.0 -0.06"/> -->
      <!-- <inertia ixx=".75" ixy="0.0" ixz="0.0"  -->
      <!-- iyy="1.4" iyz="0.0"  -->
      <!-- izz="1.6"/> -->
    <!-- </inertial> -->
    <inertial>
      <!-- Plus small (conservative) added mass -->
      <mass value="30.3"/> 
      <!-- Assume COM is 6cm below the center of the green box (13.5cm from top of vehicle) -->
      <origin xyz="0.0 0.0 -0.06"/>
      <inertia ixx="6.31" ixy="0.0" ixz="0.22" 
      iyy="10.15" iyz="0.0" 
      izz="3.93"/>
    </inertial>
    
    
  </link>

<!-- IF YOU EVER ADD MORE LINKS, MAKE SURE TO CHANGE THE BUOYANCY FRAME VECTOR FOR THE ARM BASE FRAME!!! -->

<!-- ======= Bottom Frame ======= -->
  <link name="F_R_bar">
    <visual>
      <geometry>
        <box size = "0.25 0.02 0.05"/>
      </geometry>
      <material name="black_v"/>
    </visual>
  </link>
    <joint name="FRBarJoint" type="fixed">
      <parent link="vehicle_base_link"/>
      <child link="F_R_bar"/>
      <origin rpy="0 1.57075 0" xyz="0.225 -.19 -.2"/>
    </joint>
  <link name="F_L_bar">
    <visual>
      <geometry>
        <box size = "0.25 0.02 0.05"/>
      </geometry>
      <material name="black_v"/>
    </visual>
  </link>
    <joint name="FLBarJoint" type="fixed">
      <parent link="vehicle_base_link"/>
      <child link="F_L_bar"/>
      <origin rpy="0 1.57075 0" xyz="0.225 .19 -.2"/>
    </joint>
  <link name="B_L_bar">
      <visual>
        <geometry>
          <box size = "0.25 0.02 0.05"/>
        </geometry>
        <material name="black_v"/>
      </visual>
  </link>
    <joint name="BLBarJoint" type="fixed">
      <parent link="vehicle_base_link"/>
      <child link="B_L_bar"/>
      <origin rpy="0 1.57075 0" xyz="-0.225 .19 -.2"/>
    </joint>
  <link name="B_R_bar">
    <visual>
      <geometry>
        <box size = "0.25 0.02 0.05"/>
      </geometry>
      <material name="black_v"/>
    </visual>
  </link>
    <joint name="BRBarJoint" type="fixed">
      <parent link="vehicle_base_link"/>
      <child link="B_R_bar"/>
      <origin rpy="0 1.57075 0" xyz="-0.225 -.19 -.2"/>
    </joint>
  <link name="R_bar">
    <visual>
      <geometry>
        <box size = "0.5 0.02 0.05"/>
      </geometry>
      <material name="black_v"/>
    </visual>
  </link>
    <joint name="RBarJoint" type="fixed">
      <parent link="vehicle_base_link"/>
      <child link="R_bar"/>
      <origin rpy="0 0 0" xyz="0 -.19 -.3"/>
    </joint>
  <link name="L_bar">
    <visual>
      <geometry>
        <box size = "0.5 0.02 0.05"/>
      </geometry>
      <material name="black_v"/>
    </visual>
  </link>
    <joint name="LBarJoint" type="fixed">
      <parent link="vehicle_base_link"/>
      <child link="L_bar"/>
      <origin rpy="0 0 0" xyz="0 .19 -.3"/>
    </joint>

<!-- ======= Front/Back Bumpers ======= -->
  <link name="front_bumper">
    <visual>
      <geometry>
        <cylinder length="0.4" radius="0.075"/>
      </geometry>
      <material name="green_v"/>
     </visual>
  </link>
    <joint name="fbump_link" type="fixed">
      <parent link="vehicle_base_link"/>
      <child link="front_bumper"/>
      <origin rpy="1.57579632679 0 0" xyz="0.25 0 0"/>
    </joint>
  <link name="rear_bumper">
      <visual>
        <geometry>
          <cylinder length="0.4" radius="0.075"/>
        </geometry>
        <material name="green_v"/>
      </visual>
  </link>
    <joint name="rbump_link" type="fixed">
      <parent link="vehicle_base_link"/>
      <child link="rear_bumper"/>
      <origin rpy="1.57579632679 0 0" xyz="-0.25 0 0"/>
    </joint>

<!-- ======= Front Arrow ======= -->
  <link name="l_arrow">
    <visual>
      <geometry>
        <box size="0.05 0.318 0.01"/>
      </geometry>
      <material name="black_v"/>
    </visual>
  </link>
    <joint name="l_arrow_link" type="fixed">
      <parent link="vehicle_base_link"/>
      <child link="l_arrow"/>
      <origin rpy="0 0 0.787898163397" xyz="0.05 0.095 0.075"/>
    </joint>
  <link name="r_arrow">
    <visual>
      <geometry>
        <box size="0.05 0.318 0.01"/>
      </geometry>
      <material name="black_v"/>
    </visual>
  </link>
    <joint name="r_arrow_link" type="fixed">
      <parent link="vehicle_base_link"/>
      <child link="r_arrow"/>
      <origin rpy="0 0 -0.787898163397" xyz="0.05 -0.095 0.075"/>
    </joint>

<!-- ======= Thrusters ======= -->
  <link name="sf_fan">
    <visual>
      <geometry>
        <cylinder length="0.04" radius="0.06"/>
      </geometry>
      <material name="blue_v"/>
    </visual>
  </link>
    <joint name="base_to_sf_fan" type="fixed">
      <parent link="vehicle_base_link"/>
      <child link="sf_fan"/>
      <origin rpy="0 1.57579632679 0.785" xyz="0.22 -0.12 -0.14"/>
    </joint>
  <link name="sf_thruster">
    <visual>
      <geometry>
        <cylinder length="0.1" radius="0.02"/>
      </geometry>
      <material name="black_v"/>
    </visual>
  </link>
    <joint name="sf_fan_thruster_joint" type="fixed">
      <parent link="sf_fan"/>
      <child link="sf_thruster"/>
      <origin xyz="0 0 -0.06"/>
    </joint>
  <link name="pf_fan">
    <visual>
      <geometry>
        <cylinder length="0.04" radius="0.06"/>
      </geometry>
      <material name="blue_v"/>
    </visual>
  </link>
    <joint name="base_to_pf_fan" type="fixed">
      <parent link="vehicle_base_link"/>
      <child link="pf_fan"/>
      <origin rpy="0 1.57579632679 -0.785" xyz="0.22 0.12 -0.14"/>
    </joint>
  <link name="pf_thruster">
    <visual>
      <geometry>
        <cylinder length="0.1" radius="0.02"/>
      </geometry>
      <material name="black_v"/>
    </visual>
  </link>
    <joint name="pf_fan_thruster_joint" type="fixed">
      <parent link="pf_fan"/>
      <child link="pf_thruster"/>
      <origin xyz="0 0 -0.06"/>
    </joint>
  <link name="sa_fan">
    <visual>
      <geometry>
        <cylinder length="0.04" radius="0.06"/>
      </geometry>
      <material name="blue_v"/>
    </visual>
  </link>
    <joint name="base_to_sa_fan" type="fixed">
      <parent link="vehicle_base_link"/>
      <child link="sa_fan"/>
      <origin rpy="0 -1.57579632679 -0.785" xyz="-0.22 -0.12 -0.14"/>
    </joint>
  <link name="sa_thruster">
    <visual>
      <geometry>
        <cylinder length="0.1" radius="0.02"/>
      </geometry>
      <material name="black_v"/>
    </visual>
  </link>
    <joint name="sa_fan_thruster_joint" type="fixed">
      <parent link="sa_fan"/>
      <child link="sa_thruster"/>
      <origin xyz="0 0 -0.06"/>
    </joint>
  <link name="pa_fan">
    <visual>
      <geometry>
        <cylinder length="0.04" radius="0.06"/>
      </geometry>
      <material name="blue_v"/>
    </visual>
  </link>
    <joint name="base_to_pa_fan" type="fixed">
      <parent link="vehicle_base_link"/>
      <child link="pa_fan"/>
      <origin rpy="0 -1.57579632679 0.785" xyz="-0.22 0.12 -0.14"/>
    </joint>
  <link name="pa_thruster">
    <visual>
      <geometry>
        <cylinder length="0.1" radius="0.02"/>
      </geometry>
      <material name="black_v"/>
    </visual>
  </link>
    <joint name="pa_fan_thruster_joint" type="fixed">
      <parent link="pa_fan"/>
      <child link="pa_thruster"/>
      <origin xyz="0 0 -0.06"/>
    </joint>

  <link name="seabotix_bottle">
    <visual>
      <geometry>
        <cylinder length="0.26" radius="0.05"/>
      </geometry>
      <material name="black_v"/>
    </visual>
  </link>
    <joint name="sbottle_link" type="fixed">
      <parent link="vehicle_base_link"/>
      <child link="seabotix_bottle"/>
      <origin rpy="0 1.57579632679 0" xyz="-0.05 0 -0.18"/>
    </joint>

  <joint name="arm_to_vehicle" type="fixed">
    <origin rpy="3.1415 0 0" xyz=".325 0 -.09"/>
    <parent link="vehicle_base_link"/>
    <child link="base_link"/>
  </joint>
<!-- ======================================= -->
<!--               BRAVO LINKS               -->
<!-- ======================================= -->
  <link name="base_link"/>
  <joint name="bravo_joint" type="fixed">
    <origin rpy="-1.5708 0 0" xyz="0 0 0"/>
    <parent link="base_link"/>
    <child link="bravo_base_link"/>
    <origin rpy="0 0 0" xyz="0 0 0"/>
  </joint>
  <material name="bravo_black">
    <color rgba="0.3 0.3 0.3 1"/>
  </material>
  <link name="bravo_base_link">
    <visual>
      <geometry>
        <mesh filename="C:/Users/marcu/OneDrive/Documents/GitHub/onr_compliance_julia/meshes/RS2-1019_base.obj"/>
      </geometry>
      <material name="bravo_black"/>
    </visual>
    <collision>
      <geometry>
        <box size="0.0725 0.1112 0.083"/>
      </geometry>
      <origin rpy="0 0 0" xyz="0.03625 00 0.0415"/>
    </collision>
    <collision>
      <geometry>
        <box size="0.050 0.080 0.060"/>
      </geometry>
      <origin rpy="0 0 0" xyz="0.025 -0.04556 0.03"/>
    </collision>
    <collision>
      <geometry>
        <cylinder length="0.083" radius="0.046"/>
      </geometry>
      <origin rpy="0 0 0" xyz="0.0665 0 0.0415"/>
    </collision>
  </link>

  <joint name="bravo_axis_e" type="revolute">
    <parent link="bravo_base_link"/>
    <origin rpy="0 0 3.14159" xyz="0.0665 0.08 0"/>
    <axis xyz="0 0 -1"/>
    <child link="bravo_1019_end_link"/>
    <limit effort="0" lower="0.0" upper="6.3" velocity="0"/>
  </joint>

  <link name="bravo_1019_end_link">
    <visual>
      <geometry>
        <mesh filename="C:/Users/marcu/OneDrive/Documents/GitHub/onr_compliance_julia/meshes/RS2-1019_end.obj"/>
      </geometry>
      <material name="bravo_black"/>
    </visual>
  </link>
  
  <joint name="bravo_d_base_joint" type="fixed">
    <parent link="bravo_1019_end_link"/>
    <origin rpy="0 0 3.1415" xyz="0 0 0"/>
    <child link="bravo_1013_base_link"/>
  </joint>

  <link name="bravo_1013_base_link">
    <visual>
      <geometry>
        <mesh filename="C:/Users/marcu/OneDrive/Documents/GitHub/onr_compliance_julia/meshes/RS2-1013_base.obj"/>
      </geometry>
      <material name="bravo_black"/>
    </visual>
    <collision>
      <geometry>
        <cylinder length="0.030" radius="0.046"/>
      </geometry>
      <origin rpy="0 0 0" xyz="0.0 00 0.015"/>
    </collision>
    <collision>
      <geometry>
        <cylinder length="0.1" radius="0.046"/>
      </geometry>
      <origin rpy="1.5707 0 0 " xyz="0.048 00 0.0642"/>
    </collision>
  </link>

  <joint name="bravo_axis_d" type="revolute">
    <parent link="bravo_1013_base_link"/>
    <origin rpy="0 0 0" xyz="0.046 0.0642 0"/> <!--change rotz to rotate this axis-->
    <axis xyz="0 -1 0"/>
    <child link="bravo_1013_joint_link"/>
    <limit effort="0" lower="0.0" upper="3.2" velocity="0"/>
  </joint>

  <link name="bravo_1013_joint_link">
    <visual>
      <geometry>
        <mesh filename="C:/Users/marcu/OneDrive/Documents/GitHub/onr_compliance_julia/meshes/RS2-1013_end.obj"/>
      </geometry>
      <material name="bravo_black"/>
    </visual>
    <collision>
      <geometry>
        <cylinder length="0.03" radius="0.046"/>
      </geometry>
      <origin rpy="0 0 0" xyz="0.046 0 -0.03555"/>
    </collision>
  </link>

  <joint name="bravo_1013_end_joint" type="fixed">
    <parent link="bravo_1013_joint_link"/>
    <origin rpy="3.14159 0 0" xyz="0.046 -0.05055 0.00055"/>
    <child link="bravo_1013_end_link"/>
  </joint>
  <link name="bravo_1013_end_link"/>
  <joint name="bravo_c_base_joint" type="fixed">
    <parent link="bravo_1013_end_link"/>
    <origin rpy="0 0 0" xyz="0 0.182 0"/>
    <child link="bravo_1023_0_base_link"/>
  </joint>

  <link name="bravo_1023_0_base_link">
    <visual>
      <geometry>
        <mesh filename="C:/Users/marcu/OneDrive/Documents/GitHub/onr_compliance_julia/meshes/RS2-1023_0_base.obj"/>
      </geometry>
      <material name="bravo_black"/>
    </visual>
    <collision>
      <geometry>
        <cylinder length="0.03" radius="0.0408"/>
      </geometry>
      <origin rpy="0 0 0" xyz="0 00 0.015"/>
    </collision>
    <collision>
      <geometry>
        <cylinder length="0.0816" radius="0.0408"/>
      </geometry>
      <origin rpy="1.5707 0 0" xyz="0.0408 00 0.0578"/>
    </collision>
  </link>

  <joint name="bravo_axis_c" type="revolute">
    <parent link="bravo_1023_0_base_link"/>
    <origin rpy="0 0 0" xyz="0.042 0.0578 0"/>
    <axis xyz="0 -1 0"/>
    <child link="bravo_1023_0_joint_link"/>
    <limit effort="0" lower="0.0" upper="3.2" velocity="0"/>
  </joint>

  <link name="bravo_1023_0_joint_link">
    <visual>
      <geometry>
        <mesh filename="C:/Users/marcu/OneDrive/Documents/GitHub/onr_compliance_julia/meshes/RS2-1023_0_end.obj"/>
      </geometry>
      <material name="bravo_black"/>
    </visual>
    <collision>
      <geometry>
        <cylinder length="0.080" radius="0.0408"/>
      </geometry>
      <origin rpy="0 0 0" xyz="0.0408 0 -0.05385"/>
    </collision>
  </link>

  <joint name="bravo_1023_0_end_joint" type="fixed">
    <parent link="bravo_1023_0_joint_link"/>
    <origin rpy="3.14159 0 0" xyz="0.0408 -0.09385 0"/>
    <child link="bravo_1023_0_end_link"/>
  </joint>
  <link name="bravo_1023_0_end_link"/>
  <joint name="bravo_b_base_joint" type="fixed">
    <parent link="bravo_1023_0_end_link"/>
    <origin rpy="0 0 0" xyz="0 0 0"/>
    <child link="bravo_1023_1_base_link"/>
  </joint>

  <link name="bravo_1023_1_base_link">
        </link>

  <joint name="bravo_axis_b" type="continuous">
    <parent link="bravo_1023_1_base_link"/>
    <origin rpy="0 0 0" xyz="0 0 0.0005"/>
    <axis xyz="0 0 -1"/>
    <child link="bravo_1023_1_joint_link"/>
    <limit effort="0" velocity="0" lower="0.0" upper="0.0" />
  </joint>

  <link name="bravo_1023_1_joint_link">
    <visual>
      <geometry>
        <mesh filename="C:/Users/marcu/OneDrive/Documents/GitHub/onr_compliance_julia/meshes/RS2-1023_1_end.obj"/>
      </geometry>
      <material name="bravo_black"/>
    </visual>
    <collision>
      <geometry>
        <cylinder length="0.0056" radius="0.0408"/>
      </geometry>
      <origin rpy="0 0 0" xyz="0 0 0.0028"/>
    </collision>
  </link>

  <joint name="bravo_1023_1_end_joint" type="fixed">
    <parent link="bravo_1023_1_joint_link"/>
    <origin rpy="0 0 0" xyz="0 0.0056 0"/>
    <child link="bravo_1023_1_end_link"/>
  </joint>
  <link name="bravo_1023_1_end_link"/>
  <joint name="bravo_a_base_joint" type="fixed">
    <parent link="bravo_1023_1_end_link"/>
    <origin rpy="0 0 0" xyz="0 0 0"/>
    <child link="bravo_1028_base_link"/>
  </joint>

  <link name="bravo_1028_base_link">
    <visual>
      <geometry>
        <mesh filename="C:/Users/marcu/OneDrive/Documents/GitHub/onr_compliance_julia/meshes/RS2-1028.obj"/>
      </geometry>
      <material name="bravo_black"/>
    </visual>
    <collision>
      <geometry>
        <cylinder length="0.120" radius="0.0408"/>
      </geometry>
      <origin rpy="0 0 0" xyz="0 0 0.06"/>
    </collision>
  </link>

  <joint name="bravo_1028_end_joint" type="fixed">
    <parent link="bravo_1028_base_link"/>
    <origin rpy="0 0 1.5707" xyz="0 0.120 0"/>
    <child link="bravo_1028_end_link"/>
  </joint>

  <link name="bravo_1028_end_link"/>
  <joint name="bravo_jaws_joint" type="fixed">
    <origin rpy="0 0 0" xyz=" 0 0 0.0"/>
    <parent link="bravo_1028_end_link"/>
    <child link="bravo_jaws_base_link"/>
  </joint>

    <link name="bravo_jaws_base_link">
      <visual>-->
          <geometry>
              <mesh filename="C:/Users/marcu/OneDrive/Documents/GitHub/onr_compliance_julia/meshes/end_effectors/RS2-257.obj"/>
          </geometry>
          <material name="bravo_jaws_black"/>
      </visual>
  </link>

  <link name="bravo_push_rod"/>
  <joint name="bravo_axis_a" type="prismatic">
    <origin rpy="0 0 0" xyz="0 0 0.009"/>
    <parent link="bravo_jaws_base_link"/>
    <child link="bravo_push_rod"/>
    <axis xyz="0 0 1"/>
    <limit effort="10" lower="0" upper="0.035" velocity="10"/>
  </joint>

  <link name="bravo_1030_base_link">
    <visual>
      <geometry>
        <mesh filename="C:/Users/marcu/OneDrive/Documents/GitHub/onr_compliance_julia/meshes/RS2-1030.obj"/>
      </geometry>
      <material name="bravo_black"/>
    </visual>
    <collision>
      <geometry>
        <cylinder length="0.03033333" radius="0.046"/>
      </geometry>
      <origin rpy="0 0 0" xyz="0 0 0.01516666"/>
    </collision>
    <collision>
      <geometry>
        <cylinder length="0.03033333" radius="0.045"/>
      </geometry>
      <origin rpy="0 0 0" xyz="0 0 0.0455"/>
    </collision>
    <collision>
      <geometry>
        <cylinder length="0.03033333" radius="0.044"/>
      </geometry>
      <origin rpy="0 0 0" xyz="0 0 0.075833333"/>
    </collision>
    <collision>
      <geometry>
        <cylinder length="0.03033333" radius="0.043"/>
      </geometry>
      <origin rpy="0 0 0" xyz="0 0 0.1061666666"/>
    </collision>
    <collision>
      <geometry>
        <cylinder length="0.03033333" radius="0.042"/>
      </geometry>
      <origin rpy="0 0 0" xyz="0 0 0.1365"/>
    </collision>
    <collision>
      <geometry>
        <cylinder length="0.03033333" radius="0.041"/>
      </geometry>
      <origin rpy="0 0 0" xyz="0 0 0.1668333"/>
    </collision>
  </link>

  <joint name="bravo_1030_base_joint" type="fixed">
    <parent link="bravo_1013_end_link"/>
    <child link="bravo_1030_base_link"/>
    <origin rpy="0 0 0" xyz="0 0 0"/>
  </joint>
  <material name="bravo_finger_jaws_black">
    <color rgba="0.3 0.3 0.3 1"/>
  </material>

  <joint name="bravo_finger_jaws_joint" type="fixed">
    <origin rpy="0 0 0" xyz="0 0 0"/>
    <parent link="bravo_jaws_base_link"/>
    <child link="bravo_finger_jaws_base_link"/>
    <origin rpy="0 0 0" xyz="0 0 0"/>
  </joint>
  
  <link name="bravo_finger_jaws_base_link">
    <visual>
      <geometry>
        <mesh filename="C:/Users/marcu/OneDrive/Documents/GitHub/onr_compliance_julia/meshes/end_effectors/RS2-257.obj"/>
      </geometry>
      <material name="bravo_finger_jaws_black"/>
    </visual>
    <collision>
      <geometry>
        <cylinder length="0.02" radius="0.05"/>
      </geometry>
      <origin rpy="0 1.5707 0" xyz="0.01 0 0.00"/>
    </collision>
  </link>

  <link name="bravo_finger_jaws_rs2_300_link">
    <visual>
      <geometry>
        <mesh filename="C:/Users/marcu/OneDrive/Documents/GitHub/onr_compliance_julia/meshes/end_effectors/RS2-300.obj"/>
      </geometry>
      <material name="bravo_finger_jaws_black"/>
    </visual>
    <collision>
      <geometry>
        <box size="0.14 0.04 0.045"/>
      </geometry>
      <origin rpy="0 0 0.35" xyz="0.07 0.025 0.00"/>
    </collision>
  </link>

  <joint name="bravo_finger_jaws_rs2_300_joint" type="revolute">
    <origin rpy="0 0 0" xyz="0.0097 0 0.033"/>
    <parent link="bravo_finger_jaws_base_link"/>
    <child link="bravo_finger_jaws_rs2_300_link"/>
    <axis xyz="0 0 -1"/>
    <limit effort="10" lower="0" upper="1.0" velocity="10"/>
    <mimic joint="bravo_axis_a" multiplier="18" offset="0"/>
  </joint>

  <link name="bravo_finger_jaws_rs2_301_link">
    <visual>
      <geometry>
        <mesh filename="C:/Users/marcu/OneDrive/Documents/GitHub/onr_compliance_julia/meshes/end_effectors/RS2-301.obj"/>
      </geometry>
      <material name="bravo_finger_jaws_black"/>
    </visual>
    <collision>
      <geometry>
        <box size="0.14 0.04 0.045"/>
      </geometry>
      <origin rpy="0 0 -0.35" xyz="0.07 -0.025 0.00"/>
    </collision>
  </link>

  <joint name="bravo_finger_jaws_rs2_301_joint" type="revolute">
    <origin rpy="0 0 0" xyz="0.0097 0 -0.033"/>
    <parent link="bravo_finger_jaws_base_link"/>
    <child link="bravo_finger_jaws_rs2_301_link"/>
    <axis xyz="0 0 1"/>
    <limit effort="10" lower="0" upper="1.0" velocity="10"/>
    <mimic joint="bravo_finger_jaws_rs2_300_joint" multiplier="1" offset="0"/> -->
  </joint>
</robot>