<?xml version="1.0"?>
<robot name="bravo_7" xmlns:xacro="http://ros.org/wiki/xacro">

    <!-- See K&D properties: -->
    <!-- https://blueprint-lab.github.io/Blueprint_Lab_Software/documentation/index.html -->
    <!-- https://en.wikipedia.org/wiki/Denavit%E2%80%93Hartenberg_parameters#:~:text=handed%20coordinate%20system.-,Four%20parameters,-%5Bedit%5D -->

    <xacro:property name="joint_damping" value="10.0" />
    <xacro:property name="joint_friction" value="0.0" />
    <material name="bravo_black">
        <color rgba="0.3 0.3 0.3 1. " />
    </material>
    <material name="bravo_finger_jaws_black">
        <color rgba="0.3 0.3 0.3 1. " />
    </material>

    <xacro:macro name="bravo_7" params="parent *origin  name:=bravo_7 jaw_yaw_offset:=0 with_force_torque_sensor:=false">
        <joint name="${name}_joint" type="fixed">
            <xacro:insert_block name="origin" />
            <parent link="${parent}" />
            <child link="${name}_base_link" />
            <origin xyz="0 0 0" rpy="0 0 0" />
            <dynamics damping="${joint_damping}" friction="${joint_friction}" />
        </joint>

        <link name="ee_link"/>
        <joint name="ee_link_joint" type="fixed">
            <parent link="bravo_1023_1_joint_link"/>
            <child link="ee_link"/>
            <origin rpy="0 0 -1.5707" xyz="0 0 0.120"/>
          </joint>

        <link name="bravo_base_link">
            <inertial>
                <mass value="1.25" />
                <origin xyz="-0.075 -0.006 -0.003" />
                <inertia
                ixx="${2108 * 1e-6}"
                ixy="${182 * 1e-6}"
                ixz="${-15 * 1e-6}"
                iyy="${2573 * 1e-6}"
                iyz="${-21 * 1e-6}"
                izz="${3483 * 1e-6}"
                />
            </inertial>
            <visual>
                <geometry>
                    <mesh filename="C:/Users/marcu/OneDrive/Documents/GitHub/onr_compliance_julia/meshes/RS2-1019_base.obj" />
                </geometry>
                <material name="bravo_black" />
                <origin xyz="0.0 0.0 0.0" rpy="0.0 -0.0 0.0" />
            </visual>
            <collision>
                <geometry>
                    <box size="0.0725 0.1112 0.083 " />
                </geometry>
                <origin xyz="0.03625 0.0 0.0415" rpy="0.0 0.0 0.0" />
            </collision>
            <collision>
                <geometry>
                    <box size="0.05 0.08 0.06" />
                </geometry>
                <origin xyz="0.025 -0.04556 0.03" rpy="0.0 0.0 0.0" />
            </collision>
            <collision>
                <geometry>
                    <cylinder radius="0.046" length="0.083" />
                </geometry>
                <origin xyz="0.0665 0.0 0.0415" rpy="0.0 0.0 0.0" />
            </collision>
        </link>
        <link name="bravo_1019_end_link">
            <inertial>
                <mass value="1.55" />
                <inertia
                ixx="${11442 * 1e-6}"
                ixy="${-484 * 1e-6}"
                ixz="${3405 * 1e-6}"
                iyy="${12980 * 1e-6}"
                iyz="${-1265 * 1e-6}"
                izz="${3202 * 1e-6}"
                />
                <origin xyz="0.005 -0.001 0.016" />
            </inertial>
            <visual>
                <geometry>
                    <mesh filename="C:/Users/marcu/OneDrive/Documents/GitHub/onr_compliance_julia/meshes/RS2-1019_end.obj" />
                </geometry>
                <material name="bravo_black" />
                <origin xyz="0.0 0.0 0.0" rpy="0.0 -0.0 0.0" />
            </visual>
            <visual>
                <geometry>
                    <mesh filename="C:/Users/marcu/OneDrive/Documents/GitHub/onr_compliance_julia/meshes/RS2-1013_base.obj" />
                </geometry>
                <material name="bravo_black" />
                <origin xyz="0.0 0.0 0.0" rpy="0.0 -0.0 0.0" />
            </visual>
            <collision>
                <geometry>
                    <mesh filename="C:/Users/marcu/OneDrive/Documents/GitHub/onr_compliance_julia/meshes/RS2-1019_end.obj" />
                </geometry>
                <origin xyz="0.0 0.0 0.0" rpy="0.0 -0.0 0.0" />
            </collision>
            <collision>
                <geometry>
                    <cylinder radius="0.046" length="0.03" />
                </geometry>
                <origin xyz="0.0 0.0 0.015" rpy="0.0 -0.0 0.0" />
            </collision>
            <collision>
                <geometry>
                    <cylinder radius="0.046" length="0.1" />
                </geometry>
                <origin xyz="0.048 0.0 0.0642" rpy="1.5707 -0.0 0.0" />
            </collision>
        </link>
        <link name="bravo_1013_joint_link">
            <inertial>
                <mass value="1.14" />
                <origin xyz="0.022 -0.029 0.001" />
                <inertia
                ixx="${3213 * 1e-6}"
                ixy="${-1548 * 1e-6}"
                ixz="${-31 * 1e-6}"
                iyy="${2327 * 1e-6}"
                iyz="${6 * 1e-6}"
                izz="${4340 * 1e-6}"
                />
            </inertial>
            <visual>
                <geometry>
                    <mesh filename="C:/Users/marcu/OneDrive/Documents/GitHub/onr_compliance_julia/meshes/RS2-1013_end.obj" />
                </geometry>
                <material name="bravo_black" />
                <origin xyz="0.0 0.0 0.0" rpy="0.0 -0.0 0.0" />
            </visual>
            <visual>
                <geometry>
                    <mesh filename="C:/Users/marcu/OneDrive/Documents/GitHub/onr_compliance_julia/meshes/RS2-1026_0_base.obj" />
                </geometry>
                <material name="bravo_black" />
                <origin xyz="0.04600000000128156 4.829533423884964e-07 -0.2325499999993592" rpy="3.14159 -0.0 3.14159" />
            </visual>
            <visual>
                <geometry>
                    <mesh filename="C:/Users/marcu/OneDrive/Documents/GitHub/onr_compliance_julia/meshes/RS2-1030.obj" />
                </geometry>
                <material name="bravo_black" />
                <origin xyz="0.046 0.0 -0.05055" rpy="3.14159 -0.0 3.14159" />
            </visual>
            <collision>
                <geometry>
                    <cylinder radius="0.046" length="0.03" />
                </geometry>
                <origin xyz="0.046 0.0 -0.03555" rpy="0.0 0.0 0.0" />
            </collision>
            <collision>
                <geometry>
                    <cylinder radius="0.0408" length="0.03" />
                </geometry>
                <origin xyz="0.04600000000138718 5.227571892886473e-07 -0.24754999999930644" rpy="3.14159 -0.0 3.14159" />
            </collision>
            <collision>
                <geometry>
                    <cylinder radius="0.0408" length="0.0816" />
                </geometry>
                <origin xyz="0.005200000001832204 7.445972960125356e-07 -0.29034999999915573" rpy="-1.5708953071795866 -0.0 3.14159" />
            </collision>
            <collision>
                <geometry>
                    <cylinder radius="0.046" length="0.03033333" />
                </geometry>
                <origin xyz="0.046000000000106796 4.0246094175109416e-08 -0.0657166599999466" rpy="3.14159 -0.0 3.14159" />
            </collision>
            <collision>
                <geometry>
                    <cylinder radius="0.045" length="0.03033333" />
                </geometry>
                <origin xyz="0.04600000000032039 1.207383355971241e-07 -0.0960499999998398" rpy="3.14159 -0.0 3.14159" />
            </collision>
            <collision>
                <geometry>
                    <cylinder radius="0.044" length="0.03033333" />
                </geometry>
                <origin xyz="0.04600000000053398 2.0123055844401027e-07 -0.126383332999733" rpy="3.14159 -0.0 3.14159" />
            </collision>
            <collision>
                <geometry>
                    <cylinder radius="0.043" length="0.03033333" />
                </geometry>
                <origin xyz="0.046000000000747575 2.817227828830503e-07 -0.15671666659962621" rpy="3.14159 -0.0 3.14159" />
            </collision>
            <collision>
                <geometry>
                    <cylinder radius="0.042" length="0.03033333" />
                </geometry>
                <origin xyz="0.04600000000096117 3.6221500679137236e-07 -0.18704999999951943" rpy="3.14159 -0.0 3.14159" />
            </collision>
            <collision>
                <geometry>
                    <cylinder radius="0.041" length="0.03033333" />
                </geometry>
                <origin xyz="0.04600000000117476 4.427071420697953e-07 -0.21738329999941264" rpy="3.14159 -0.0 3.14159" />
            </collision>
        </link>
        <link name="bravo_1026_0_joint_link">
            <inertial>
                <origin xyz="0.017 -0.026 -0.002" rpy="0.0 -0.0 0.0" />
                <mass value="1.14" />
                <inertia
                ixx="${21232* 1e-6}"
                ixy="${330 * 1e-6}"
                ixz="${-3738 * 1e-6}"
                iyy="${22252 * 1e-6}"
                iyz="${-1278 * 1e-6}"
                izz="${2054 * 1e-6}"
                />
            </inertial>
            <visual>
                <geometry>
                    <mesh filename="C:/Users/marcu/OneDrive/Documents/GitHub/onr_compliance_julia/meshes/RS2-1026_0_end.obj" />
                </geometry>
                <material name="bravo_black" />
                <origin xyz="0.0 0.0 0.0" rpy="0.0 -0.0 0.0" />
            </visual>
            <collision>
                <geometry>
                    <cylinder radius="0.0408" length="0.08" />
                </geometry>
                <origin xyz="0.0408 0.0 -0.05385" rpy="0.0 0.0 0.0" />
            </collision>
        </link>
        <link name="bravo_1026_1_joint_link">
            <inertial>
                <mass value="1.03" />
                <origin xyz="0.020 -0.024 0.001" />
                <inertia
                ixx="${2430 * 1e-6}"
                ixy="${-1144 * 1e-6}"
                ixz="${-40 * 1e-6}"
                iyy="${2026 * 1e-6}"
                iyz="${11 * 1e-6}"
                izz="${3330 * 1e-6}"
                />
            </inertial>
            <visual>
                <geometry>
                    <mesh filename="C:/Users/marcu/OneDrive/Documents/GitHub/onr_compliance_julia/meshes/RS2-1026_1_end.obj" />
                </geometry>
                <material name="bravo_black" />
                <origin xyz="0.0 0.0 0.0" rpy="0.0 0.0 3.14159" />
            </visual>
            <visual>
                <geometry>
                    <mesh filename="C:/Users/marcu/OneDrive/Documents/GitHub/onr_compliance_julia/meshes/RS2-1023_0_base.obj" />
                </geometry>
                <material name="bravo_black" />
                <origin xyz="0.0 0.0 0.0056" rpy="0.0 -0.0 3.14159" />
            </visual>
            <collision>
                <geometry>
                    <cylinder radius="0.0408" length="0.0056" />
                </geometry>
                <origin xyz="0.0 0.0 0.0028" rpy="0.0 0.0 3.14159" />
            </collision>
            <collision>
                <geometry>
                    <cylinder radius="0.0408" length="0.03" />
                </geometry>
                <origin xyz="0.0 0.0 0.0206" rpy="0.0 -0.0 3.14159" />
            </collision>
            <collision>
                <geometry>
                    <cylinder radius="0.0408" length="0.0816" />
                </geometry>
                <origin xyz="-0.040799999999856354 1.082664635687914e-07 0.0634" rpy="1.5707 -0.0 3.14159" />
            </collision>
        </link>
        <link name="bravo_1023_0_joint_link">
            <inertial>
                <origin xyz="0.0 0.003 -0.098" rpy="0.0 -0.0 0.0" />
                <mass value="0.333" />
                <inertia ixx="0.003709" ixy="-2e-06" ixz="-4e-06" iyy="0.003734" iyz="0.0" izz="7.9e-05" />
            </inertial>
            <visual>
                <geometry>
                    <mesh filename="C:/Users/marcu/OneDrive/Documents/GitHub/onr_compliance_julia/meshes/RS2-1023_0_end.obj" />
                </geometry>
                <material name="bravo_black" />
                <origin xyz="0.0 0.0 0.0" rpy="0.0 -0.0 0.0" />
            </visual>
            <collision>
                <geometry>
                    <cylinder radius="0.0408" length="0.08" />
                </geometry>
                <origin xyz="0.0408 0.0 -0.05385" rpy="0.0 0.0 0.0" />
            </collision>
        </link>
        <link name="bravo_1023_1_joint_link">
            <inertial>
                <origin xyz="0.0 0.003 -0.098" />
                <mass value="1.04" />
                <inertia
                ixx="${22359 * 1e-6}"
                ixy="${1 * 1e-6}"
                ixz="${-19 * 1e-6}"
                iyy="${22363 * 1e-6}"
                iyz="${15 * 1e-6}"
                izz="${936 * 1e-6}"
                />
            </inertial>
            <visual>
                <geometry>
                    <mesh filename="C:/Users/marcu/OneDrive/Documents/GitHub/onr_compliance_julia/meshes/RS2-1023_1_end.obj" />
                </geometry>
                <material name="bravo_black" />
                <origin xyz="0.0 0.0 0.0" rpy="0.0 -0.0 0.0" />
            </visual>
            <visual>
                <geometry>
                    <mesh filename="C:/Users/marcu/OneDrive/Documents/GitHub/onr_compliance_julia/meshes/RS2-1028.obj" />
                </geometry>
                <material name="bravo_black" />
                <origin xyz="0.0 0.0 0.0056" rpy="0.0 -0.0 0.0" />
            </visual>
            <visual>
                <geometry>
                    <mesh filename="C:/Users/marcu/OneDrive/Documents/GitHub/onr_compliance_julia/meshes/end_effectors/RS2-257.obj" />
                </geometry>
                <material name="bravo_finger_jaws_black" />
                <origin xyz="0.0 0.0 0.1256" rpy="-1.5707 -1.5706999999997038 0.0" />
            </visual>
            <collision>
                <geometry>
                    <cylinder radius="0.0408" length="0.0056" />
                </geometry>
                <origin xyz="0.0 0.0 0.0028" rpy="0.0 0.0 0.0" />
            </collision>
            <collision>
                <geometry>
                    <cylinder radius="0.0408" length="0.12" />
                </geometry>
                <origin xyz="0.0 0.0 0.06559999999999999" rpy="0.0 -0.0 0.0" />
            </collision>
            <collision>
                <geometry>
                    <cylinder radius="0.05" length="0.02" />
                </geometry>
                <origin xyz="9.632679474766714e-07 0.0 0.13559999995360572" rpy="-9.632679489654805e-05 -9.631751559834678e-05 -1.5706999907215955" />
            </collision>
        </link>
        <link name="bravo_push_rod">
            <inertial>
                <origin xyz="0.0 0.0 0.0" rpy="0.0 -0.0 0.0" />
                <mass value="0.1" />
                <inertia ixx="0.0001" ixy="0.0" ixz="0.0" iyy="0.0001" iyz="0.0" izz="0.0001" />
            </inertial>
        </link>
        <link name="bravo_finger_jaws_rs2_300_link">
            <inertial>
                <origin xyz="0.05 0.0 0.0" rpy="0.0 -0.0 0.0" />
                <mass value="0.24" />
                <inertia ixx="0.000244" ixy="-1.2e-05" ixz="0.0" iyy="0.00113" iyz="1e-06" izz="0.001178" />
            </inertial>
            <visual>
                <geometry>
                    <mesh filename="C:/Users/marcu/OneDrive/Documents/GitHub/onr_compliance_julia/meshes/end_effectors/RS2-300.obj" />
                </geometry>
                <material name="bravo_finger_jaws_black" />
                <origin xyz="0.0 0.0 0.0" rpy="0.0 -0.0 0.0" />
            </visual>
            <collision>
                <geometry>
                    <mesh filename="C:/Users/marcu/OneDrive/Documents/GitHub/onr_compliance_julia/meshes/end_effectors/RS2-300.obj" />
                </geometry>
                <origin xyz="0.0 0.0 0.0" rpy="0.0 -0.0 0.0" />
            </collision>
        </link>
        <link name="bravo_finger_jaws_rs2_301_link">
            <inertial>
                <origin xyz="0.05 0.0 0.0" rpy="0.0 -0.0 0.0" />
                <mass value="0.24" />
                <inertia ixx="0.000244" ixy="-1.2e-05" ixz="0.0" iyy="0.00113" iyz="1e-06" izz="0.001178" />
            </inertial>
            <visual>
                <geometry>
                    <mesh filename="C:/Users/marcu/OneDrive/Documents/GitHub/onr_compliance_julia/meshes/end_effectors/RS2-301.obj" />
                </geometry>
                <material name="bravo_finger_jaws_black" />
                <origin xyz="0.0 0.0 0.0" rpy="0.0 -0.0 0.0" />
            </visual>
            <collision>
                <geometry>
                    <mesh filename="C:/Users/marcu/OneDrive/Documents/GitHub/onr_compliance_julia/meshes/end_effectors/RS2-301.obj" />
                </geometry>
                <origin xyz="0.0 0.0 0.0" rpy="0.0 -0.0 0.0" />
            </collision>
        </link>
        <joint name="bravo_axis_g" type="revolute">
            <dynamics damping="${joint_damping}" friction="${joint_friction}" />
            <limit effort="500.0" velocity="6.0" lower="0.0" upper="6.2" />
            <parent link="bravo_base_link" />
            <child link="bravo_1019_end_link" />
            <axis xyz=" 0.  0. -1." />
            <origin xyz="0.0665 0.0 0.08" rpy="0.0 0.0 3.14159" />
        </joint>
        <joint name="bravo_axis_a" type="prismatic">
            <dynamics damping="${joint_damping}" friction="${joint_friction}" />
            <limit effort="1000.0" velocity="10.0" lower="0.0" upper="0.035" />
            <parent link="bravo_1023_1_joint_link" />
            <child link="bravo_push_rod" />
            <axis xyz="0. 0. 1." />
            <origin xyz="-8.669411487068951e-07 0.008999999958245167 0.12560000008350966" rpy="-1.5707 -1.5706999999997038 0.0" />
        </joint>
        <joint name="bravo_finger_jaws_rs2_300_joint" type="revolute">
            <limit effort="400.0" velocity="6.0" lower="0.0" upper="1.0" />
            <!-- The multiplier may need to be recalibrated every time the gripper is mounted. -->
            <mimic joint="bravo_axis_a" multiplier="32.0" offset="0.0" />
            <parent link="bravo_1023_1_joint_link" />
            <child link="bravo_finger_jaws_rs2_300_link" />
            <axis xyz=" 0.  0. -1." />
            <origin xyz="-0.032999065323888854 -3.178784226673016e-06 0.1353031787392095" rpy="-1.5707 -1.5706999999997038 0.0" />
        </joint>
        <joint name="bravo_finger_jaws_rs2_301_joint" type="revolute">
            <limit effort="400.0" velocity="6.0" lower="0.0" upper="1.0" />
            <mimic joint="bravo_finger_jaws_rs2_300_joint" multiplier="1.0" offset="0.0" />
            <parent link="bravo_1023_1_joint_link" />
            <child link="bravo_finger_jaws_rs2_301_link" />
            <axis xyz="0. 0. 1." />
            <origin xyz="0.03300093406370696 3.178784226673016e-06 0.13529682117078565" rpy="-1.5707 -1.5706999999997038 0.0" />
        </joint>

        <!-- Optionally include an additional cylindrical link and fixed joint if F/T sensor installed -->
        <xacro:if value="$(arg with_force_torque_sensor)">
            <link name="bravo_ft_sensor_link">
                <inertial>
                    <mass value="0.25" />
                    <origin xyz="0 0 ${0.042 / 2}" />
                    <!-- I_z = 1/2 * m * r^2 -->
                    <!-- I_x = I_y = 1/12 * m * (3 * r^2 + h^2) -->
                    <inertia
                    ixx="${1500 * 1e-6}"
                    ixy="0"
                    ixz="0"
                    iyy="${1500 * 1e-6}"
                    iyz="0"
                    izz="${2260 * 1e-6}"
                    />
                </inertial>
                <visual>
                    <geometry>
                        <cylinder length="0.042" radius="${0.083 / 2}" />
                    </geometry>
                    <material name="bravo_black" />
                    <origin xyz="0.0 0.0 ${0.042 / 2}" rpy="0.0 0.0 0.0" />
                </visual>
                <collision>
                    <geometry>
                        <cylinder length="0.042" radius="${0.083 / 2}" />
                    </geometry>
                    <material name="bravo_black" />
                    <origin xyz="0.0 0.0 ${0.042 / 2}" rpy="0.0 0.0 0.0" />
                </collision>
            </link>

            <joint name="bravo_axis_b" type="revolute">
                <dynamics damping="${joint_damping}" friction="${joint_friction}" />
                <limit effort="500.0" velocity="6.0" lower="0" upper="6.28" />
                <parent link="bravo_1023_0_joint_link" />
                <child link="bravo_ft_sensor_link" />
                <axis xyz=" 0.  0. -1." />
                <origin xyz="0.0408 -1.326794896676365e-09 -0.09434999999999824" rpy="3.14159 -0.0 ${jaw_yaw_offset}" />
            </joint>

            <joint name="bravo_ft_fixed_joint" type="fixed">
                <parent link="bravo_ft_sensor_link" />
                <child link="bravo_1023_1_joint_link" />
                <axis xyz=" 0.  0. -1." />
                <origin xyz="0 0 0.042" rpy="0 0 0" />
            </joint>
        </xacro:if>
        <xacro:unless value="$(arg with_force_torque_sensor)">
            <!-- 1023_1_joint_link (forearm) attached directly to 1023_0_join_link (elbow) -->
            <joint name="bravo_axis_b" type="revolute">
                <dynamics damping="${joint_damping}" friction="${joint_friction}" />
                <limit effort="500.0" velocity="6.0" lower="0" upper="6.28" />
                <parent link="bravo_1023_0_joint_link" />
                <child link="bravo_1023_1_joint_link" />
                <axis xyz=" 0.  0. -1." />
                <origin xyz="0.0408 -1.326794896676365e-09 -0.09434999999999824" rpy="3.14159 -0.0 ${jaw_yaw_offset}" />
            </joint>
        </xacro:unless>

        <joint name="bravo_axis_c" type="revolute">
            <dynamics damping="${joint_damping}" friction="${joint_friction}" />
            <limit effort="500.0" velocity="6.0" lower="0.0" upper="3.14" />
            <parent link="bravo_1026_1_joint_link" />
            <child link="bravo_1023_0_joint_link" />
            <axis xyz=" 0. -1.  0." />
            <origin xyz="-0.041999999999852135 1.1145077132081467e-07 0.0634" rpy="0.0 -0.0 3.14159" />
        </joint>
        <joint name="bravo_axis_d" type="revolute">
            <dynamics damping="${joint_damping}" friction="${joint_friction}" />
            <limit effort="500.0" velocity="6.0" lower="0.0" upper="6.2" />
            <parent link="bravo_1026_0_joint_link" />
            <child link="bravo_1026_1_joint_link" />
            <axis xyz=" 0.  0. -1." />
            <origin xyz="0.0408 -1.326794896676365e-09 -0.09434999999999824" rpy="3.14159 -0.0 0.0" />
        </joint>
        <joint name="bravo_axis_e" type="revolute">
            <dynamics damping="${joint_damping}" friction="${joint_friction}" />
            <limit effort="500.0" velocity="6.0" lower="0.0" upper="3.14" />
            <parent link="bravo_1013_joint_link" />
            <child link="bravo_1026_0_joint_link" />
            <axis xyz=" 0. -1.  0." />
            <origin xyz="0.0040000000018364235 7.477816037645589e-07 -0.29034999999915573" rpy="3.14159 -0.0 3.14159" />
        </joint>
        <joint name="bravo_axis_f" type="revolute">
            <dynamics damping="${joint_damping}" friction="${joint_friction}" />
            <limit effort="500.0" velocity="6.0" lower="0.0" upper="3.14" />
            <parent link="bravo_1019_end_link" />
            <child link="bravo_1013_joint_link" />
            <axis xyz=" 0. -1.  0." />
            <origin xyz="0.046 0.0 0.0642" rpy="0.0 -0.0 0.0" />
        </joint>


    </xacro:macro>

</robot>