<?xml version="1.0" ?>
<!-- =================================================================================== -->
<!-- |    This document was autogenerated by xacro from bravo_7_example.urdf.xacro     | -->
<!-- |    EDITING THIS FILE BY HAND IS NOT RECOMMENDED                                 | -->
<!-- =================================================================================== -->
<robot name="bravo_7_example">
  <!-- See K&D properties: -->
  <!-- https://blueprint-lab.github.io/Blueprint_Lab_Software/documentation/index.html -->
  <!-- https://en.wikipedia.org/wiki/Denavit%E2%80%93Hartenberg_parameters#:~:text=handed%20coordinate%20system.-,Four%20parameters,-%5Bedit%5D -->
  <material name="bravo_black">
    <color rgba="0.3 0.3 0.3 1. "/>
  </material>
  <material name="bravo_finger_jaws_black">
    <color rgba="0.3 0.3 0.3 1. "/>
  </material>
  <link name="world"/>
  <joint name="bravo_joint" type="fixed">
    <origin rpy="1.5709 0 0" xyz="0 0 0"/>    <!-- Old rpy="0 0 0" ________________________________________________________________-->
    <parent link="world"/>
    <child link="bravo_base_link"/>
    <origin rpy="0 0 0" xyz="0 0 0"/>
    <dynamics damping="10.0" friction="0.0"/>
  </joint>
  <link name="ee_link"/>
  <joint name="ee_link_joint" type="fixed">
    <parent link="bravo_1023_1_joint_link"/>
    <child link="ee_link"/>
    <origin rpy="0 0 -1.5707" xyz="0 0 0.120"/>
  </joint>
  <link name="bravo_base_link">
    <inertial>
      <mass value="1.25"/>
      <origin xyz="-0.075 -0.006 -0.003"/>
      <inertia ixx="0.002108" ixy="0.00018199999999999998" ixz="-1.4999999999999999e-05" iyy="0.0025729999999999998" iyz="-2.1e-05" izz="0.003483"/>
    </inertial>
    <visual>
      <geometry>
        <mesh filename="C:/Users/marcu/OneDrive/Documents/GitHub/onr_compliance_julia/meshes/RS2-1019_base.obj"/>
      </geometry>
      <material name="bravo_black"/>
      <origin rpy="0.0 -0.0 0.0" xyz="0.0 0.0 0.0"/>
    </visual>
    <collision>
      <geometry>
        <box size="0.0725 0.1112 0.083 "/>
      </geometry>
      <origin rpy="0.0 0.0 0.0" xyz="0.03625 0.0 0.0415"/>
    </collision>
    <collision>
      <geometry>
        <box size="0.05 0.08 0.06"/>
      </geometry>
      <origin rpy="0.0 0.0 0.0" xyz="0.025 -0.04556 0.03"/>
    </collision>
    <collision>
      <geometry>
        <cylinder length="0.083" radius="0.046"/>
      </geometry>
      <origin rpy="0.0 0.0 0.0" xyz="0.0665 0.0 0.0415"/>
    </collision>
  </link>
  <link name="bravo_1019_end_link">
    <inertial>
      <mass value="1.55"/>
      <inertia ixx="0.011441999999999999" ixy="-0.000484" ixz="0.003405" iyy="0.01298" iyz="-0.0012649999999999998" izz="0.003202"/>
      <origin xyz="0.005 -0.001 0.016"/>
    </inertial>
    <visual>
      <geometry>
        <mesh filename="C:/Users/marcu/OneDrive/Documents/GitHub/onr_compliance_julia/meshes/RS2-1019_end.obj"/>
      </geometry>
      <material name="bravo_black"/>
      <origin rpy="0.0 -0.0 0.0" xyz="0.0 0.0 0.0"/>
    </visual>
    <visual>
      <geometry>
        <mesh filename="C:/Users/marcu/OneDrive/Documents/GitHub/onr_compliance_julia/meshes/RS2-1013_base.obj"/>
      </geometry>
      <material name="bravo_black"/>
      <origin rpy="0.0 -0.0 3.1415" xyz="0.0 0.0 0.0"/>    <!-- Old rpy="0 0 0" ________________________________________________________________-->
    </visual>
    <collision>
      <geometry>
        <mesh filename="C:/Users/marcu/OneDrive/Documents/GitHub/onr_compliance_julia/meshes/RS2-1019_end.obj"/>
      </geometry>
      <origin rpy="0.0 -0.0 0.0" xyz="0.0 0.0 0.0"/>
    </collision>
    <collision>
      <geometry>
        <cylinder length="0.03" radius="0.046"/>
      </geometry>
      <origin rpy="0.0 -0.0 0.0" xyz="0.0 0.0 0.015"/>
    </collision>
    <collision>
      <geometry>
        <cylinder length="0.1" radius="0.046"/>
      </geometry>
      <origin rpy="1.5707 -0.0 0.0" xyz="0.048 0.0 0.0642"/>
    </collision>
  </link>
  <link name="bravo_1013_joint_link">
    <inertial>
      <mass value="1.14"/>
      <origin xyz="0.022 -0.029 0.001"/>
      <inertia ixx="0.0032129999999999997" ixy="-0.001548" ixz="-3.1e-05" iyy="0.002327" iyz="6e-06" izz="0.00434"/>
    </inertial>
    <visual>
      <geometry>
        <mesh filename="C:/Users/marcu/OneDrive/Documents/GitHub/onr_compliance_julia/meshes/RS2-1013_end.obj"/>
      </geometry>
      <material name="bravo_black"/>
      <origin rpy="0.0 -0.0 0" xyz="0 0 0"/>
    </visual>
    <visual>
      <geometry>
        <mesh filename="C:/Users/marcu/OneDrive/Documents/GitHub/onr_compliance_julia/meshes/RS2-1026_0_base.obj"/>
      </geometry>
      <material name="bravo_black"/>
      <origin rpy="0.0 -0.0 3.14159" xyz="0.04600000000128156 -0.23255 0"/> <!--Old: rpy="3.14159 -0.0 3.14159" xyz="0.04600000000128156 4.829533423884964e-07 -0.2325499999993592"/>-->
    </visual>
    <visual>
      <geometry>
        <mesh filename="C:/Users/marcu/OneDrive/Documents/GitHub/onr_compliance_julia/meshes/RS2-1030.obj"/>
      </geometry>
      <material name="bravo_black"/>
      <origin rpy="3.14159 -0.0 0" xyz="0.046 -0.05055 0"/> <!--Old: rpy="3.14159 -0.0 3.14159" xyz="0.046 0.0 -0.05055"/>__________________________________________________________-->
    </visual>
    <collision>
      <geometry>
        <cylinder length="0.03" radius="0.046"/>
      </geometry>
      <origin rpy="0.0 0.0 0.0" xyz="0.046 0.0 -0.03555"/>
    </collision>
    <collision>
      <geometry>
        <cylinder length="0.03" radius="0.0408"/>
      </geometry>
      <origin rpy="3.14159 -0.0 3.14159" xyz="0.04600000000138718 5.227571892886473e-07 -0.24754999999930644"/>
    </collision>
    <collision>
      <geometry>
        <cylinder length="0.0816" radius="0.0408"/>
      </geometry>
      <origin rpy="-1.5708953071795866 -0.0 3.14159" xyz="0.005200000001832204 7.445972960125356e-07 -0.29034999999915573"/>
    </collision>
    <collision>
      <geometry>
        <cylinder length="0.03033333" radius="0.046"/>
      </geometry>
      <origin rpy="3.14159 -0.0 3.14159" xyz="0.046000000000106796 4.0246094175109416e-08 -0.0657166599999466"/>
    </collision>
    <collision>
      <geometry>
        <cylinder length="0.03033333" radius="0.045"/>
      </geometry>
      <origin rpy="3.14159 -0.0 3.14159" xyz="0.04600000000032039 1.207383355971241e-07 -0.0960499999998398"/>
    </collision>
    <collision>
      <geometry>
        <cylinder length="0.03033333" radius="0.044"/>
      </geometry>
      <origin rpy="3.14159 -0.0 3.14159" xyz="0.04600000000053398 2.0123055844401027e-07 -0.126383332999733"/>
    </collision>
    <collision>
      <geometry>
        <cylinder length="0.03033333" radius="0.043"/>
      </geometry>
      <origin rpy="3.14159 -0.0 3.14159" xyz="0.046000000000747575 2.817227828830503e-07 -0.15671666659962621"/>
    </collision>
    <collision>
      <geometry>
        <cylinder length="0.03033333" radius="0.042"/>
      </geometry>
      <origin rpy="3.14159 -0.0 3.14159" xyz="0.04600000000096117 3.6221500679137236e-07 -0.18704999999951943"/>
    </collision>
    <collision>
      <geometry>
        <cylinder length="0.03033333" radius="0.041"/>
      </geometry>
      <origin rpy="3.14159 -0.0 3.14159" xyz="0.04600000000117476 4.427071420697953e-07 -0.21738329999941264"/>
    </collision>
  </link>
  <link name="bravo_1026_0_joint_link">
    <inertial>
      <origin rpy="0.0 -0.0 0.0" xyz="0.017 -0.026 -0.002"/>
      <mass value="1.14"/>
      <inertia ixx="0.021231999999999997" ixy="0.00033" ixz="-0.003738" iyy="0.022251999999999997" iyz="-0.0012779999999999998" izz="0.002054"/>
    </inertial>
    <visual>
      <geometry>
        <mesh filename="C:/Users/marcu/OneDrive/Documents/GitHub/onr_compliance_julia/meshes/RS2-1026_0_end.obj"/>
      </geometry>
      <material name="bravo_black"/>
      <origin rpy="0.0 -0.0 0.0" xyz="0.0 0.0 0.0"/>
    </visual>
    <collision>
      <geometry>
        <cylinder length="0.08" radius="0.0408"/>
      </geometry>
      <origin rpy="0.0 0.0 0.0" xyz="0.0408 0.0 -0.05385"/>
    </collision>
  </link>
  <link name="bravo_1026_1_joint_link">
    <inertial>
      <mass value="1.03"/>
      <origin xyz="0.020 -0.024 0.001"/>
      <inertia ixx="0.00243" ixy="-0.001144" ixz="-3.9999999999999996e-05" iyy="0.002026" iyz="1.1e-05" izz="0.00333"/>
    </inertial>
    <visual>
      <geometry>
        <mesh filename="C:/Users/marcu/OneDrive/Documents/GitHub/onr_compliance_julia/meshes/RS2-1026_1_end.obj"/>
      </geometry>
      <material name="bravo_black"/>
      <origin rpy="0.0 3.14159 0" xyz="0.0 0.0 0.0056"/> <!-- Old: rpy="0.0 0.0 3.14159" xyz="0.0 0.0 0.0"/>_________________________________________________________________-->
    </visual>
    <visual>
      <geometry>
        <mesh filename="C:/Users/marcu/OneDrive/Documents/GitHub/onr_compliance_julia/meshes/RS2-1023_0_base.obj"/>
      </geometry>
      <material name="bravo_black"/>
      <origin rpy="0.0 3.14159 0.0" xyz="0.0 0.0 0.0056"/> <!-- Old: rpy="0.0 -0.0 3.14159" xyz="0.0 0.0 0.0056"/>___________________________________________________________-->
    </visual>
    <collision>
      <geometry>
        <cylinder length="0.0056" radius="0.0408"/>
      </geometry>
      <origin rpy="0.0 0.0 3.14159" xyz="0.0 0.0 0.0028"/>
    </collision>
    <collision>
      <geometry>
        <cylinder length="0.03" radius="0.0408"/>
      </geometry>
      <origin rpy="0.0 -0.0 3.14159" xyz="0.0 0.0 0.0206"/>
    </collision>
    <collision>
      <geometry>
        <cylinder length="0.0816" radius="0.0408"/>
      </geometry>
      <origin rpy="1.5707 -0.0 3.14159" xyz="-0.040799999999856354 1.082664635687914e-07 0.0634"/>
    </collision>
  </link>
  <link name="bravo_1023_0_joint_link">
    <inertial>
      <origin rpy="0.0 -0.0 0.0" xyz="0.0 0.003 -0.098"/>
      <mass value="0.333"/>
      <inertia ixx="0.003709" ixy="-2e-06" ixz="-4e-06" iyy="0.003734" iyz="0.0" izz="7.9e-05"/>
    </inertial>
    <visual>
      <geometry>
        <mesh filename="C:/Users/marcu/OneDrive/Documents/GitHub/onr_compliance_julia/meshes/RS2-1023_0_end.obj"/>
      </geometry>
      <material name="bravo_black"/>
      <origin rpy="0.0 -0.0 0.0" xyz="0.0 0.0 0.0"/>
    </visual>
    <collision>
      <geometry>
        <cylinder length="0.08" radius="0.0408"/>
      </geometry>
      <origin rpy="0.0 0.0 0.0" xyz="0.0408 0.0 -0.05385"/>
    </collision>
  </link>
  <link name="bravo_1023_1_joint_link">
    <inertial>
      <origin xyz="0.0 0.003 -0.098"/>
      <mass value="1.04"/>
      <inertia ixx="0.022359" ixy="1e-06" ixz="-1.8999999999999998e-05" iyy="0.022362999999999997" iyz="1.4999999999999999e-05" izz="0.000936"/>
    </inertial>
    <visual>
      <geometry>
        <mesh filename="C:/Users/marcu/OneDrive/Documents/GitHub/onr_compliance_julia/meshes/RS2-1023_1_end.obj"/>
      </geometry>
      <material name="bravo_black"/>
      <origin rpy="0.0 -0.0 0.0" xyz="0.0 0.0 0.0"/>
    </visual>
    <visual>
      <geometry>
        <mesh filename="C:/Users/marcu/OneDrive/Documents/GitHub/onr_compliance_julia/meshes/RS2-1028.obj"/>
      </geometry>
      <material name="bravo_black"/>
      <origin rpy="0.0 -0.0 0.0" xyz="0.0 0.0056 0.0"/> <!-- Old: rpy="0.0 -0.0 0.0" xyz="0.0 0.0 0.0056"/>_______________________________________________________________________-->
    </visual>
    <visual>
      <geometry>
        <mesh filename="C:/Users/marcu/OneDrive/Documents/GitHub/onr_compliance_julia/meshes/end_effectors/RS2-257.obj"/>
      </geometry>
      <material name="bravo_finger_jaws_black"/>
      <origin rpy="3.14159 0 1.57" xyz="0.0 0.1256 0"/> <!-- Old: rpy="-1.5707 -1.5706999999997038 0.0" xyz="0.0 0.0 0.1256"/>____________________________________________________-->
    </visual>
    <collision>
      <geometry>
        <cylinder length="0.0056" radius="0.0408"/>
      </geometry>
      <origin rpy="0.0 0.0 0.0" xyz="0.0 0.0 0.0028"/>
    </collision>
    <collision>
      <geometry>
        <cylinder length="0.12" radius="0.0408"/>
      </geometry>
      <origin rpy="0.0 -0.0 0.0" xyz="0.0 0.0 0.06559999999999999"/>
    </collision>
    <collision>
      <geometry>
        <cylinder length="0.02" radius="0.05"/>
      </geometry>
      <origin rpy="-9.632679489654805e-05 -9.631751559834678e-05 -1.5706999907215955" xyz="9.632679474766714e-07 0.0 0.13559999995360572"/>
    </collision>
  </link>
  <link name="bravo_push_rod">
    <inertial>
      <origin rpy="0.0 -0.0 0.0" xyz="0.0 0.0 0.0"/>
      <mass value="0.1"/>
      <inertia ixx="0.0001" ixy="0.0" ixz="0.0" iyy="0.0001" iyz="0.0" izz="0.0001"/>
    </inertial>
  </link>
  <link name="bravo_finger_jaws_rs2_300_link">
    <inertial>
      <origin rpy="0.0 -0.0 0.0" xyz="0.05 0.0 0.0"/>
      <mass value="0.24"/>
      <inertia ixx="0.000244" ixy="-1.2e-05" ixz="0.0" iyy="0.00113" iyz="1e-06" izz="0.001178"/>
    </inertial>
    <visual>
      <geometry>
        <mesh filename="C:/Users/marcu/OneDrive/Documents/GitHub/onr_compliance_julia/meshes/end_effectors/RS2-300.obj"/>
      </geometry>
      <material name="bravo_finger_jaws_black"/>
      <origin rpy="0.0 -0.0 0.0" xyz="0.0 0.0 0.0"/>
    </visual>
    <collision>
      <geometry>
        <mesh filename="C:/Users/marcu/OneDrive/Documents/GitHub/onr_compliance_julia/meshes/end_effectors/RS2-300.obj"/>
      </geometry>
      <origin rpy="0.0 -0.0 0.0" xyz="0.0 0.0 0.0"/>
    </collision>
  </link>
  <link name="bravo_finger_jaws_rs2_301_link">
    <inertial>
      <origin rpy="0.0 -0.0 0.0" xyz="0.05 0.0 0.0"/>
      <mass value="0.24"/>
      <inertia ixx="0.000244" ixy="-1.2e-05" ixz="0.0" iyy="0.00113" iyz="1e-06" izz="0.001178"/>
    </inertial>
    <visual>
      <geometry>
        <mesh filename="C:/Users/marcu/OneDrive/Documents/GitHub/onr_compliance_julia/meshes/end_effectors/RS2-301.obj"/>
      </geometry>
      <material name="bravo_finger_jaws_black"/>
      <origin rpy="0.0 -0.0 0.0" xyz="0.0 0.0 0.0"/>
    </visual>
    <collision>
      <geometry>
        <mesh filename="C:/Users/marcu/OneDrive/Documents/GitHub/onr_compliance_julia/meshes/end_effectors/RS2-301.obj"/>
      </geometry>
      <origin rpy="0.0 -0.0 0.0" xyz="0.0 0.0 0.0"/>
    </collision>
  </link>
  <joint name="bravo_axis_g" type="revolute">
    <dynamics damping="10.0" friction="0.0"/>
    <limit effort="500.0" lower="0.0" upper="6.2" velocity="3.0"/>
    <parent link="bravo_base_link"/>
    <child link="bravo_1019_end_link"/>
    <axis xyz=" 0.  0. -1."/>
    <origin rpy="0.0 0.0 3.14159" xyz="0.0665 0.08 0.0"/> <!-- Old: rpy="0.0 0.0 3.14159" xyz="0.0665 0.0 0.08"/>___________________________________________________-->
  </joint>
  <joint name="bravo_axis_a" type="prismatic">
    <dynamics damping="10.0" friction="0.0"/>
    <limit effort="1000.0" lower="0.0" upper="0.035" velocity="10.0"/>
    <parent link="bravo_1023_1_joint_link"/>
    <child link="bravo_push_rod"/>
    <axis xyz="0. 0. 1."/>
    <origin rpy="-1.5707 -1.5706999999997038 0.0" xyz="-8.669411487068951e-07 0.008999999958245167 0.12560000008350966"/>
  </joint>
  <joint name="bravo_finger_jaws_rs2_300_joint" type="revolute">
    <limit effort="400.0" lower="0.0" upper="1.0" velocity="3.0"/>
    <mimic joint="bravo_axis_a" multiplier="18.0" offset="0.0"/>
    <parent link="bravo_1023_1_joint_link"/>
    <child link="bravo_finger_jaws_rs2_300_link"/>
    <axis xyz=" 0.  0. -1."/>
    <origin rpy="0 3.14159 -1.5707" xyz="0 0.13529682117078565 -0.033"/> <!-- Old: rpy="-1.5707 -1.5706999999997038 0.0" xyz="-0.032999065323888854 -3.178784226673016e-06 0.1353031787392095"/>-->
  </joint>
  <joint name="bravo_finger_jaws_rs2_301_joint" type="revolute">
    <limit effort="400.0" lower="0.0" upper="1.0" velocity="3.0"/>
    <mimic joint="bravo_finger_jaws_rs2_300_joint" multiplier="1.0" offset="0.0"/>
    <parent link="bravo_1023_1_joint_link"/>
    <child link="bravo_finger_jaws_rs2_301_link"/>
    <axis xyz="0. 0. 1."/>
    <origin rpy="0 3.14159 -1.5707" xyz="0 0.13529682117078565 0.033"/> <!-- Old: rpy="-1.5707 -1.5706999999997038 0.0" xyz="0.03300093406370696 3.178784226673016e-06 0.13529682117078565"/>-->
  </joint>
  <joint name="bravo_axis_b" type="continuous">
    <dynamics damping="10.0" friction="0.0"/>
    <limit effort="500.0" lower="0.0" upper="6.2" velocity="3.0"/>
    <parent link="bravo_1023_0_joint_link"/>
    <child link="bravo_1023_1_joint_link"/>
    <axis xyz=" 0.  0. -1."/>
    <origin rpy="3.14159 -0.0 0" xyz="0.0408 -0.09434999999999824 0"/> <!-- Old: rpy="3.14159 -0.0 0.6" xyz="0.0408 -1.326794896676365e-09 -0.09434999999999824"/>____________________________-->
  </joint>
  <joint name="bravo_axis_c" type="revolute">
    <dynamics damping="10.0" friction="0.0"/>
    <limit effort="500.0" lower="0.0" upper="3.2" velocity="3.0"/>
    <parent link="bravo_1026_1_joint_link"/>
    <child link="bravo_1023_0_joint_link"/>
    <axis xyz=" 0. -1.  0."/>
    <origin rpy="0.0 3.14159 3.14159" xyz="-0.041999999999852135 0.0634 0"/> <!-- Old: rpy="0.0 -0.0 3.14159" xyz="-0.041999999999852135 1.1145077132081467e-07 0.0634"/>______________________-->
  </joint>
  <joint name="bravo_axis_d" type="revolute">
    <dynamics damping="10.0" friction="0.0"/>
    <limit effort="500.0" lower="0.0" upper="6.2" velocity="3.0"/>
    <parent link="bravo_1026_0_joint_link"/>
    <child link="bravo_1026_1_joint_link"/>
    <axis xyz=" 0.  0. -1."/>
    <origin rpy="3.14159 -0.0 0.0" xyz="0.0408 -0.09434999999999824 0.0056"/> <!-- Old: rpy="3.14159 -0.0 0.0" xyz="0.0408 -1.326794896676365e-09 -0.09434999999999824"/>______________________-->
  </joint>
  <joint name="bravo_axis_e" type="revolute">
    <dynamics damping="10.0" friction="0.0"/>
    <limit effort="500.0" lower="0.0" upper="3.14" velocity="3.0"/>
    <parent link="bravo_1013_joint_link"/>
    <child link="bravo_1026_0_joint_link"/>
    <axis xyz=" 0. -1.  0."/>
    <origin rpy="0 0 0" xyz="0 -0.29035 0"/> <!-- Old: rpy="3.14159 -0.0 3.14159" xyz="0.0040000000018364235 7.477816037645589e-07 -0.29034999999915573"/>_____________________________________-->
  </joint>
  <joint name="bravo_axis_f" type="revolute">
    <dynamics damping="10.0" friction="0.0"/>
    <limit effort="500.0" lower="0.0" upper="3.14" velocity="3.0"/>
    <parent link="bravo_1019_end_link"/>
    <child link="bravo_1013_joint_link"/>
    <axis xyz=" 0. -1.  0."/>
    <origin rpy="0.0 -0.0 3.14159" xyz="-0.046 -0.0642 0"/> <!-- Old: rpy="0.0 -0.0 0.0" xyz="0.046 0.0 0.0642"/>______________________________________________________________________________-->
  </joint>
  <gazebo>
    <plugin filename="libroboticsgroup_upatras_gazebo_mimic_joint_plugin.so" name="bravo_finger_jaws_rs2_300_jointmimic_joint_plugin">
      <joint>bravo_axis_a</joint>
      <mimicJoint>bravo_finger_jaws_rs2_300_joint</mimicJoint>
      <multiplier>18.0</multiplier>
      <offset>0</offset>
      <sensitiveness>0.0</sensitiveness>
      <!-- if absolute difference between setpoint and process value is below this threshold, do nothing; 0.0 = disable [rad] -->
      <maxEffort>400.0</maxEffort>
      <robotNamespace>bravo</robotNamespace>
    </plugin>
  </gazebo>
  <gazebo>
    <plugin filename="libroboticsgroup_upatras_gazebo_mimic_joint_plugin.so" name="bravo_finger_jaws_rs2_301_jointmimic_joint_plugin">
      <joint>bravo_axis_a</joint>
      <mimicJoint>bravo_finger_jaws_rs2_301_joint</mimicJoint>
      <multiplier>18.0</multiplier>
      <offset>0</offset>
      <sensitiveness>0.0</sensitiveness>
      <!-- if absolute difference between setpoint and process value is below this threshold, do nothing; 0.0 = disable [rad] -->
      <maxEffort>400.0</maxEffort>
      <robotNamespace>bravo</robotNamespace>
    </plugin>
  </gazebo>
  <!-- axis_g -->
  <gazebo reference="bravo_axis_g">
    <implicitSpringDamper>1</implicitSpringDamper>
  </gazebo>
  <!-- axis_f -->
  <gazebo reference="bravo_axis_f">
    <implicitSpringDamper>1</implicitSpringDamper>
  </gazebo>
  <!-- axis_e -->
  <gazebo reference="bravo_axis_e">
    <implicitSpringDamper>1</implicitSpringDamper>
  </gazebo>
  <!-- axis_d -->
  <gazebo reference="bravo_axis_d">
    <implicitSpringDamper>1</implicitSpringDamper>
  </gazebo>
  <!-- axis_c -->
  <gazebo reference="bravo_axis_c">
    <implicitSpringDamper>1</implicitSpringDamper>
  </gazebo>
  <!-- axis_b -->
  <gazebo reference="bravo_axis_b">
    <implicitSpringDamper>1</implicitSpringDamper>
  </gazebo>
  <!-- axis_a -->
  <gazebo reference="bravo_axis_a">
    <implicitSpringDamper>1</implicitSpringDamper>
  </gazebo>
  <!-- Links (added for all links with collision geometry -->
  <gazebo reference="bravo_base_link">
    <mu1>0.2</mu1>
    <mu2>0.2</mu2>
    <turnGravityOff>true</turnGravityOff>
    <!-- gravity is turned off in all these links because moveit_servo + roscontrol don't have gravity compensation built in. -->
  </gazebo>
  <gazebo reference="bravo_1019_end_link">
    <mu1>0.2</mu1>
    <mu2>0.2</mu2>
    <turnGravityOff>true</turnGravityOff>
  </gazebo>
  <!-- 1013_joint_link -->
  <gazebo reference="bravo_1013_joint_link">
    <mu1>0.2</mu1>
    <mu2>0.2</mu2>
    <turnGravityOff>true</turnGravityOff>
  </gazebo>
  <!-- 1026_0_joint_link -->
  <gazebo reference="bravo_1026_0_joint_link">
    <mu1>0.2</mu1>
    <mu2>0.2</mu2>
    <turnGravityOff>true</turnGravityOff>
  </gazebo>
  <!-- 1026_1_joint_link -->
  <gazebo reference="bravo_1026_1_joint_link">
    <mu1>0.2</mu1>
    <mu2>0.2</mu2>
    <turnGravityOff>true</turnGravityOff>
  </gazebo>
  <!-- 1023_0_joint_link -->
  <gazebo reference="bravo_1023_0_joint_link">
    <mu1>0.2</mu1>
    <mu2>0.2</mu2>
    <turnGravityOff>true</turnGravityOff>
  </gazebo>
  <!-- 1023_1_joint_link -->
  <gazebo reference="bravo_1023_1_joint_link">
    <mu1>0.2</mu1>
    <mu2>0.2</mu2>
    <turnGravityOff>true</turnGravityOff>
  </gazebo>
  <gazebo reference="bravo_push_rod">
    <turnGravityOff>true</turnGravityOff>
  </gazebo>
  <!-- Finger 1 -->
  <gazebo reference="bravo_finger_jaws_rs2_300_link">
    <material>Gazebo/Grey</material>
    <mu1>100.0</mu1>
    <mu2>100.0</mu2>
    <turnGravityOff>true</turnGravityOff>
  </gazebo>
  <!-- Finger 2 -->
  <gazebo reference="bravo_finger_jaws_rs2_301_link">
    <material>Gazebo/Grey</material>
    <mu1>100.0</mu1>
    <mu2>100.0</mu2>
    <turnGravityOff>true</turnGravityOff>
  </gazebo>
  <!-- Joint Transmissions -->
  <transmission name="trans_bravo_axis_g">
    <type>transmission_interface/SimpleTransmission</type>
    <joint name="bravo_axis_g">
      <hardwareInterface>hardware_interface/EffortJointInterface</hardwareInterface>
    </joint>
    <actuator name="bravo_axis_g_motor">
      <hardwareInterface>hardware_interface/EffortJointInterface</hardwareInterface>
      <mechanicalReduction>1</mechanicalReduction>
    </actuator>
  </transmission>
  <transmission name="trans_bravo_axis_f">
    <type>transmission_interface/SimpleTransmission</type>
    <joint name="bravo_axis_f">
      <hardwareInterface>hardware_interface/EffortJointInterface</hardwareInterface>
    </joint>
    <actuator name="bravo_axis_f_motor">
      <hardwareInterface>hardware_interface/EffortJointInterface</hardwareInterface>
      <mechanicalReduction>1</mechanicalReduction>
    </actuator>
  </transmission>
  <transmission name="trans_bravo_axis_e">
    <type>transmission_interface/SimpleTransmission</type>
    <joint name="bravo_axis_e">
      <hardwareInterface>hardware_interface/EffortJointInterface</hardwareInterface>
    </joint>
    <actuator name="bravo_axis_e_motor">
      <hardwareInterface>hardware_interface/EffortJointInterface</hardwareInterface>
      <mechanicalReduction>1</mechanicalReduction>
    </actuator>
  </transmission>
  <transmission name="trans_bravo_axis_d">
    <type>transmission_interface/SimpleTransmission</type>
    <joint name="bravo_axis_d">
      <hardwareInterface>hardware_interface/EffortJointInterface</hardwareInterface>
    </joint>
    <actuator name="bravo_axis_d_motor">
      <hardwareInterface>hardware_interface/EffortJointInterface</hardwareInterface>
      <mechanicalReduction>1</mechanicalReduction>
    </actuator>
  </transmission>
  <transmission name="trans_bravo_axis_c">
    <type>transmission_interface/SimpleTransmission</type>
    <joint name="bravo_axis_c">
      <hardwareInterface>hardware_interface/EffortJointInterface</hardwareInterface>
    </joint>
    <actuator name="bravo_axis_c_motor">
      <hardwareInterface>hardware_interface/EffortJointInterface</hardwareInterface>
      <mechanicalReduction>1</mechanicalReduction>
    </actuator>
  </transmission>
  <transmission name="trans_bravo_axis_b">
    <type>transmission_interface/SimpleTransmission</type>
    <joint name="bravo_axis_b">
      <hardwareInterface>hardware_interface/EffortJointInterface</hardwareInterface>
    </joint>
    <actuator name="bravo_axis_b_motor">
      <hardwareInterface>hardware_interface/EffortJointInterface</hardwareInterface>
      <mechanicalReduction>1</mechanicalReduction>
    </actuator>
  </transmission>
  <transmission name="trans_bravo_axis_a">
    <type>transmission_interface/SimpleTransmission</type>
    <joint name="bravo_axis_a">
      <hardwareInterface>hardware_interface/EffortJointInterface</hardwareInterface>
    </joint>
    <actuator name="bravo_axis_a_motor">
      <hardwareInterface>hardware_interface/EffortJointInterface</hardwareInterface>
      <mechanicalReduction>1</mechanicalReduction>
    </actuator>
  </transmission>
  <gazebo>
    <plugin filename="libgazebo_ros_control.so" name="gazebo_ros_control">
      <robotNamespace>bravo</robotNamespace>
      <legacyModeNS>True</legacyModeNS>
    </plugin>
  </gazebo>
  <!-- A box to emulate the depth camera -->
  <!-- <link name="depth_cam_link">
    <pose>0 0 0 0 0 0</pose>
    <visual>
      <origin rpy="0 0 0" xyz="-0.05 0 -0.02"/>
      <geometry>
        <box size="0.05 0.12 0.07"/>
      </geometry>
      <material name="Orange">
        <color rgba="0.84 0.246 0.035 1.0"/>
      </material>
    </visual>
    <collision>
      <origin rpy="0 0 0" xyz="-0.05 0 -0.02"/>
      <geometry>
        <box size="0.05 0.12 0.07"/>
      </geometry>
    </collision>
  </link> -->
  <!-- workaround for rotated kinect output -->
  <!-- https://answers.gazebosim.org/question/4266/gazebo-15-libgazebo_openni_kinectso-pointcloud-data-is-rotated-and-flipped/?answer=26388#post-id-26388 -->
  <!-- <link name="kinect_optical_link"/>
  <joint name="depth_cam_to_kinect_optical_link" type="fixed">
    <parent link="depth_cam_link"/>
    <child link="kinect_optical_link"/>
    <origin rpy="-1.5708 0 -1.5708"/>
  </joint>
  <gazebo reference="depth_cam_link">
    <static>1</static>
    <sensor name="camera" type="depth">
      <updateRate>30.0</updateRate>
      <camera>
        <horizontal_fov>1.047</horizontal_fov>
        <image>
          <width>300</width>
          <height>300</height>
          <format>R8G8B8</format>
        </image>
        <clip>
          <near>0.25</near>
          <far>100</far>
        </clip>
      </camera>
      <!http://gazebosim.org/tutorials/?tut=ros_depth_camera -->
      <!-- <plugin filename="libgazebo_ros_openni_kinect.so" name="camera_plugin">
        <baseline>0.2</baseline>
        <alwaysOn>true</alwaysOn>
        <Keep this zero, update_rate in the parent <sensor> tag
            will control the frame rate. -->
        <!-- <updateRate>0.0</updateRate>
        <cameraName>camera_ir</cameraName>
        <imageTopicName>/camera/color/image_raw</imageTopicName>
        <cameraInfoTopicName>/camera/color/camera_info</cameraInfoTopicName>
        <depthImageTopicName>/camera/depth/image_raw</depthImageTopicName>
        <depthImageCameraInfoTopicName>/camera/depth/camera_info</depthImageCameraInfoTopicName>
        <pointCloudTopicName>/camera/depth/points</pointCloudTopicName>
        <frameName>/kinect_optical_link</frameName>
        <pointCloudCutoff>0.1</pointCloudCutoff>
        <pointCloudCutoffMax>3.0</pointCloudCutoffMax>
        <distortionK1>0</distortionK1>
        <distortionK2>0</distortionK2>
        <distortionK3>0</distortionK3>
        <distortionT1>0</distortionT1>
        <distortionT2>0</distortionT2>
        <CxPrime>0</CxPrime>
        <Cx>0</Cx>
        <Cy>0</Cy>
        <focalLength>0</focalLength>
        <hackBaseline>0</hackBaseline>
      </plugin>
    </sensor>
  </gazebo> -->
  <!--
        The depth camera is mounted parallel to the jaws on the wrist, but is
        measured from a frame coincident with bravo_1028_base_link. So we add a
        virtual link to account for the jaw_yaw_offset roll calibration, with the
        same origin but a slight roll.
        -->
  <!-- <link name="depth_cam_measurement_link"/>
  <joint name="jaw_offset_frame" type="fixed">
    <parent link="bravo_1023_1_joint_link"/>
    <child link="depth_cam_measurement_link"/>
    <origin rpy="0 0 0" xyz="0 0 0"/>
  </joint>
  <joint name="depth_cam_measurement" type="fixed">
    <parent link="depth_cam_measurement_link"/>
    <child link="depth_cam_link"/>
    <origin rpy="1.5708 -1.5708 0" xyz="-0.006 -0.078 0.070"/>
  </joint> -->
</robot>

