<?xml version="1.0" encoding="utf-8"?>
<!-- =================================================================================== -->
<!-- |    This document was autogenerated by xacro from test_reach5mini.urdf.xacro     | -->
<!-- |    EDITING THIS FILE BY HAND IS NOT RECOMMENDED                                 | -->
<!-- |    Unless you're Marcus Rosette or Hannah Kolano or Scott Chow  -->
<!-- =================================================================================== -->
<!-- when doing STL -> OBJ conversion, use this to keep origins: https://blender.stackexchange.com/questions/26451/how-to-move-a-complex-object-to-the-origin-without-destroying-it -->
<robot name="bravo_toy_saab">
  <!-- ======================================= -->
  <!-- - - - - - - - MATERIALS - - - - - - - - -->
  <!-- ======================================= -->
    <material name="bravo_black">
      <color rgba="0.3 0.3 0.3 1. "/>
    </material>
    <material name="bravo_finger_jaws_black">
      <color rgba="0.3 0.3 0.3 1. "/>
    </material>
    <material name="green_v">
      <color rgba="0.5 0.9 0.3 1"/>
    </material>
    <material name="black">
      <color rgba="0 0 0 1"/>
    </material>
    <material name="black_v">
      <color rgba="0 0 0 1"/>
    </material>
    <material name="blue_v">
      <color rgba="0.2 0.4 0.6 1"/>
    </material>
    <material name="orange_v">
      <color rgba="1 .4 0 1"/>
    </material>
    <material name="grey_v">
      <color rgba=".3 .3 .3 1"/>
    </material>
    <material name="red_v">
      <color rgba="1 0 0 1"/>
    </material>
    <material name="yellow_v">
      <color rgba="1 1 0 1"/>
    </material>


  <!-- ======================================= -->
  <!--             VEHICLE LINKS               -->
  <!-- ======================================= -->
  <link name="vehicle_base_link">
    <visual>
      <geometry>
        <box size="0.85 0.6 0.15"/>
      </geometry>
      <material name="yellow_v"/>
    </visual>
    <inertial>
      <mass value="30"/> 
      <origin xyz="0.0 0.0 -0.06"/>
      <inertia ixx="6.31" ixy="0.0" ixz="0.22" 
      iyy="10.15" iyz="0.0" 
      izz="3.93"/>
    </inertial>
  </link>

  <link name="bottom_body_link">
    <visual>
      <geometry>
        <box size="0.85 0.56 0.15"/>
      </geometry>
      <material name="yellow_v"/>
    </visual>
    <inertial>
      <mass value="30"/> 
      <origin xyz="0.0 0.0 -0.06"/>
      <inertia ixx="6.31" ixy="0.0" ixz="0.22" 
      iyy="10.15" iyz="0.0" 
      izz="3.93"/>
    </inertial>
  </link>
  <joint name="bottom_body_joint" type="fixed">
    <parent link="vehicle_base_link"/>
    <child link="bottom_body_link"/>
    <origin rpy="0 0 0" xyz="0 0 -.35"/>
  </joint>


<!-- IF YOU EVER ADD MORE LINKS, MAKE SURE TO CHANGE THE BUOYANCY FRAME VECTOR FOR THE ARM BASE FRAME!!! -->

<!-- ======= Bottom Frame ======= -->
  <link name="F_R_bar">
    <visual>
      <geometry>
        <box size = "0.35 0.02 0.05"/>
      </geometry>
      <material name="black_v"/>
    </visual>
  </link>
    <joint name="FRBarJoint" type="fixed">
      <parent link="vehicle_base_link"/>
      <child link="F_R_bar"/>
      <origin rpy="0 1.57075 0" xyz="0.4 -.29 -.25"/>
    </joint>
  <link name="F_L_bar">
    <visual>
      <geometry>
        <box size = "0.35 0.02 0.05"/>
      </geometry>
      <material name="black_v"/>
    </visual>
  </link>
    <joint name="FLBarJoint" type="fixed">
      <parent link="vehicle_base_link"/>
      <child link="F_L_bar"/>
      <origin rpy="0 1.57075 0" xyz="0.4 .29 -.25"/>
    </joint>
  <link name="B_L_bar">
      <visual>
        <geometry>
          <box size = "0.35 0.02 0.05"/>
        </geometry>
        <material name="black_v"/>
      </visual>
  </link>
    <joint name="BLBarJoint" type="fixed">
      <parent link="vehicle_base_link"/>
      <child link="B_L_bar"/>
      <origin rpy="0 1.57075 0" xyz="-0.4 .29 -.25"/>
    </joint>
  <link name="B_R_bar">
    <visual>
      <geometry>
        <box size = "0.35 0.02 0.05"/>
      </geometry>
      <material name="black_v"/>
    </visual>
  </link>
    <joint name="BRBarJoint" type="fixed">
      <parent link="vehicle_base_link"/>
      <child link="B_R_bar"/>
      <origin rpy="0 1.57075 0" xyz="-0.4 -.29 -.25"/>
    </joint>
  <link name="R_bar">
    <visual>
      <geometry>
        <box size = "0.85 0.02 0.05"/>
      </geometry>
      <material name="black_v"/>
    </visual>
  </link>
    <joint name="RBarJoint" type="fixed">
      <parent link="vehicle_base_link"/>
      <child link="R_bar"/>
      <origin rpy="0 0 0" xyz="0 -.29 -.4"/>
    </joint>
  <link name="L_bar">
    <visual>
      <geometry>
        <box size = "0.85 0.02 0.05"/>
      </geometry>
      <material name="black_v"/>
    </visual>
  </link>
    <joint name="LBarJoint" type="fixed">
      <parent link="vehicle_base_link"/>
      <child link="L_bar"/>
      <origin rpy="0 0 0" xyz="0 .29 -.4"/>
    </joint>

<!-- ======= Front/Back Bumpers ======= -->
  <link name="front_bumper">
    <visual>
      <geometry>
        <cylinder length="0.6" radius="0.075"/>
      </geometry>
      <material name="yellow_v"/>
     </visual>
  </link>
    <joint name="fbump_link" type="fixed">
      <parent link="vehicle_base_link"/>
      <child link="front_bumper"/>
      <origin rpy="1.57579632679 0 0" xyz="0.425 0 0"/>
    </joint>
  <link name="rear_bumper">
      <visual>
        <geometry>
          <cylinder length="0.6" radius="0.075"/>
        </geometry>
        <material name="yellow_v"/>
      </visual>
  </link>
    <joint name="rbump_link" type="fixed">
      <parent link="vehicle_base_link"/>
      <child link="rear_bumper"/>
      <origin rpy="1.57579632679 0 0" xyz="-0.425 0 0"/>
    </joint>

<!-- ======= Front Arrow ======= -->
  <link name="l_arrow">
    <visual>
      <geometry>
        <box size="0.05 0.318 0.01"/>
      </geometry>
      <material name="black_v"/>
    </visual>
  </link>
    <joint name="l_arrow_link" type="fixed">
      <parent link="vehicle_base_link"/>
      <child link="l_arrow"/>
      <origin rpy="0 0 0.787898163397" xyz="0.05 0.095 0.075"/>
    </joint>
  <link name="r_arrow">
    <visual>
      <geometry>
        <box size="0.05 0.318 0.01"/>
      </geometry>
      <material name="black_v"/>
    </visual>
  </link>
    <joint name="r_arrow_link" type="fixed">
      <parent link="vehicle_base_link"/>
      <child link="r_arrow"/>
      <origin rpy="0 0 -0.787898163397" xyz="0.05 -0.095 0.075"/>
    </joint>

<!-- ======= Thrusters ======= -->
  <link name="sf_fan">
    <visual>
      <geometry>
        <cylinder length="0.04" radius="0.06"/>
      </geometry>
      <material name="blue_v"/>
    </visual>
  </link>
    <joint name="base_to_sf_fan" type="fixed">
      <parent link="vehicle_base_link"/>
      <child link="sf_fan"/>
      <origin rpy="0 1.57579632679 0.785" xyz="0.22 -0.12 -0.14"/>
    </joint>
  <link name="sf_thruster">
    <visual>
      <geometry>
        <cylinder length="0.1" radius="0.02"/>
      </geometry>
      <material name="black_v"/>
    </visual>
  </link>
    <joint name="sf_fan_thruster_joint" type="fixed">
      <parent link="sf_fan"/>
      <child link="sf_thruster"/>
      <origin xyz="0 0 -0.06"/>
    </joint>
  <link name="pf_fan">
    <visual>
      <geometry>
        <cylinder length="0.04" radius="0.06"/>
      </geometry>
      <material name="blue_v"/>
    </visual>
  </link>
    <joint name="base_to_pf_fan" type="fixed">
      <parent link="vehicle_base_link"/>
      <child link="pf_fan"/>
      <origin rpy="0 1.57579632679 -0.785" xyz="0.22 0.12 -0.14"/>
    </joint>
  <link name="pf_thruster">
    <visual>
      <geometry>
        <cylinder length="0.1" radius="0.02"/>
      </geometry>
      <material name="black_v"/>
    </visual>
  </link>
    <joint name="pf_fan_thruster_joint" type="fixed">
      <parent link="pf_fan"/>
      <child link="pf_thruster"/>
      <origin xyz="0 0 -0.06"/>
    </joint>
  <link name="sa_fan">
    <visual>
      <geometry>
        <cylinder length="0.04" radius="0.06"/>
      </geometry>
      <material name="blue_v"/>
    </visual>
  </link>
    <joint name="base_to_sa_fan" type="fixed">
      <parent link="vehicle_base_link"/>
      <child link="sa_fan"/>
      <origin rpy="0 -1.57579632679 -0.785" xyz="-0.22 -0.12 -0.14"/>
    </joint>
  <link name="sa_thruster">
    <visual>
      <geometry>
        <cylinder length="0.1" radius="0.02"/>
      </geometry>
      <material name="black_v"/>
    </visual>
  </link>
    <joint name="sa_fan_thruster_joint" type="fixed">
      <parent link="sa_fan"/>
      <child link="sa_thruster"/>
      <origin xyz="0 0 -0.06"/>
    </joint>
  <link name="pa_fan">
    <visual>
      <geometry>
        <cylinder length="0.04" radius="0.06"/>
      </geometry>
      <material name="blue_v"/>
    </visual>
  </link>
    <joint name="base_to_pa_fan" type="fixed">
      <parent link="vehicle_base_link"/>
      <child link="pa_fan"/>
      <origin rpy="0 -1.57579632679 0.785" xyz="-0.22 0.12 -0.14"/>
    </joint>
  <link name="pa_thruster">
    <visual>
      <geometry>
        <cylinder length="0.1" radius="0.02"/>
      </geometry>
      <material name="black_v"/>
    </visual>
  </link>
    <joint name="pa_fan_thruster_joint" type="fixed">
      <parent link="pa_fan"/>
      <child link="pa_thruster"/>
      <origin xyz="0 0 -0.06"/>
    </joint>

  <link name="seabotix_bottle">
    <visual>
      <geometry>
        <cylinder length="0.26" radius="0.05"/>
      </geometry>
      <material name="black_v"/>
    </visual>
  </link>
    <joint name="sbottle_link" type="fixed">
      <parent link="vehicle_base_link"/>
      <child link="seabotix_bottle"/>
      <origin rpy="0 1.57579632679 0" xyz="-0.05 0 -0.18"/>
    </joint>


<!-- ======================================= -->
<!--               BRAVO LINKS               -->
<!-- ======================================= -->
  <joint name="bravo_joint" type="fixed">
    <origin rpy="1.57079 0 0" xyz=".425 0 -.39"/>    <!-- Old rpy="0 0 0" xyz=".325 0 -.09" ________________________________________________________________-->
    <parent link="vehicle_base_link"/>
    <child link="bravo_base_link"/>
    <dynamics damping="10.0" friction="0.0"/>
  </joint>

  <link name="bravo_base_link">
    <inertial>
      <mass value="1.25"/>
      <origin xyz="-0.075 -0.006 -0.003"/>
      <inertia ixx="0.002108" ixy="0.00018199999999999998" ixz="-1.4999999999999999e-05" iyy="0.0025729999999999998" iyz="-2.1e-05" izz="0.003483"/>
    </inertial>
    <visual>
      <geometry>
        <mesh filename="C:/Users/marcu/OneDrive/Documents/GitHub/onr_compliance_julia/meshes/RS2-1019_base.obj"/>
      </geometry>
      <material name="bravo_black"/>
      <origin rpy="0.0 -0.0 0.0" xyz="0.0 0.0 0.0"/>
    </visual>
    <collision>
      <geometry>
        <box size="0.0725 0.1112 0.083 "/>
      </geometry>
      <origin rpy="0.0 0.0 0.0" xyz="0.03625 0.0 0.0415"/>
    </collision>
    <collision>
      <geometry>
        <box size="0.05 0.08 0.06"/>
      </geometry>
      <origin rpy="0.0 0.0 0.0" xyz="0.025 -0.04556 0.03"/>
    </collision>
    <collision>
      <geometry>
        <cylinder length="0.083" radius="0.046"/>
      </geometry>
      <origin rpy="0.0 0.0 0.0" xyz="0.0665 0.0 0.0415"/>
    </collision>
  </link>

  <!-- Changed bravo_axis_g to fixed -->
  <joint name="bravo_axis_g" type="fixed">  
    <dynamics damping="10.0" friction="0.0"/>
    <limit effort="500.0" lower="0.0" upper="6.2" velocity="3.0"/>
    <parent link="bravo_base_link"/>
    <child link="bravo_1019_end_link"/>
    <axis xyz=" 0. -1. 0."/>
    <origin rpy="0.0 0.0 3.14159" xyz="0.0665 0.08 0.0"/> <!-- Old: rpy="0.0 0.0 3.14159" xyz="0.0665 0.0 0.08"/>___________________________________________________-->
  </joint>

  <link name="bravo_1019_end_link">
    <inertial>
      <mass value="1.55"/>
      <inertia ixx="0.011441999999999999" ixy="-0.000484" ixz="0.003405" iyy="0.01298" iyz="-0.0012649999999999998" izz="0.003202"/>
      <origin xyz="0.005 -0.001 0.016"/>
    </inertial>
    <visual>
      <geometry>
        <mesh filename="C:/Users/marcu/OneDrive/Documents/GitHub/onr_compliance_julia/meshes/RS2-1019_end.obj"/>
      </geometry>
      <material name="bravo_black"/>
      <origin rpy="0.0 -0.0 0.0" xyz="0.0 0.0 0.0"/>
    </visual>
    <visual>
      <geometry>
        <mesh filename="C:/Users/marcu/OneDrive/Documents/GitHub/onr_compliance_julia/meshes/RS2-1013_base.obj"/>
      </geometry>
      <material name="bravo_black"/>
      <origin rpy="0.0 -0.0 3.1415" xyz="0.0 0.0 0.0"/>    <!-- Old rpy="0 0 0" ________________________________________________________________-->
    </visual>
    <collision>
      <geometry>
        <mesh filename="C:/Users/marcu/OneDrive/Documents/GitHub/onr_compliance_julia/meshes/RS2-1019_end.obj"/>
      </geometry>
      <origin rpy="0.0 -0.0 0.0" xyz="0.0 0.0 0.0"/>
    </collision>
    <collision>
      <geometry>
        <cylinder length="0.03" radius="0.046"/>
      </geometry>
      <origin rpy="0.0 -0.0 0.0" xyz="0.0 0.0 0.015"/>
    </collision>
    <collision>
      <geometry>
        <cylinder length="0.1" radius="0.046"/>
      </geometry>
      <origin rpy="1.5707 -0.0 0.0" xyz="0.048 0.0 0.0642"/>
    </collision>
  </link>

  <joint name="bravo_axis_f" type="revolute">
    <dynamics damping="10.0" friction="0.0"/>
    <limit effort="500.0" lower="0.0" upper="3.14" velocity="3.0"/>
    <parent link="bravo_1019_end_link"/>
    <child link="bravo_1013_joint_link"/>
    <axis xyz=" 0. 0. 1."/>
    <origin rpy="0.0 -0.0 3.14159" xyz="-0.046 -0.0642 0"/> <!-- Old: rpy="0.0 -0.0 0.0" xyz="0.046 0.0 0.0642"/>______________________________________________________________________________-->
  </joint>

  <link name="bravo_1013_joint_link">
    <inertial>
      <mass value="1.14"/>
      <origin xyz="0.022 -0.029 0.001"/>
      <inertia ixx="0.0032129999999999997" ixy="-0.001548" ixz="-3.1e-05" iyy="0.002327" iyz="6e-06" izz="0.00434"/>
    </inertial>
    <visual>
      <geometry>
        <mesh filename="C:/Users/marcu/OneDrive/Documents/GitHub/onr_compliance_julia/meshes/RS2-1013_end.obj"/>
      </geometry>
      <material name="bravo_black"/>
      <origin rpy="0.0 -0.0 0.0" xyz="0.0 0.0 0.0"/>
    </visual>
    <visual>
      <geometry>
        <mesh filename="C:/Users/marcu/OneDrive/Documents/GitHub/onr_compliance_julia/meshes/RS2-1026_0_base.obj"/>
      </geometry>
      <material name="bravo_black"/>
      <origin rpy="0.0 -0.0 3.14159" xyz="0.04600000000128156 -0.23255 0"/> <!--Old: rpy="3.14159 -0.0 3.14159" xyz="0.04600000000128156 4.829533423884964e-07 -0.2325499999993592"/>-->
    </visual>
    <visual>
      <geometry>
        <mesh filename="C:/Users/marcu/OneDrive/Documents/GitHub/onr_compliance_julia/meshes/RS2-1030.obj"/>
      </geometry>
      <material name="bravo_black"/>
      <origin rpy="3.14159 -0.0 0" xyz="0.046 -0.05055 0"/> <!--Old: rpy="3.14159 -0.0 3.14159" xyz="0.046 0.0 -0.05055"/>__________________________________________________________-->
    </visual>
    <collision>
      <geometry>
        <cylinder length="0.03" radius="0.046"/>
      </geometry>
      <origin rpy="0.0 0.0 0.0" xyz="0.046 0.0 -0.03555"/>
    </collision>
    <collision>
      <geometry>
        <cylinder length="0.03" radius="0.0408"/>
      </geometry>
      <origin rpy="3.14159 -0.0 3.14159" xyz="0.04600000000138718 5.227571892886473e-07 -0.24754999999930644"/>
    </collision>
    <collision>
      <geometry>
        <cylinder length="0.0816" radius="0.0408"/>
      </geometry>
      <origin rpy="-1.5708953071795866 -0.0 3.14159" xyz="0.005200000001832204 7.445972960125356e-07 -0.29034999999915573"/>
    </collision>
    <collision>
      <geometry>
        <cylinder length="0.03033333" radius="0.046"/>
      </geometry>
      <origin rpy="3.14159 -0.0 3.14159" xyz="0.046000000000106796 4.0246094175109416e-08 -0.0657166599999466"/>
    </collision>
    <collision>
      <geometry>
        <cylinder length="0.03033333" radius="0.045"/>
      </geometry>
      <origin rpy="3.14159 -0.0 3.14159" xyz="0.04600000000032039 1.207383355971241e-07 -0.0960499999998398"/>
    </collision>
    <collision>
      <geometry>
        <cylinder length="0.03033333" radius="0.044"/>
      </geometry>
      <origin rpy="3.14159 -0.0 3.14159" xyz="0.04600000000053398 2.0123055844401027e-07 -0.126383332999733"/>
    </collision>
    <collision>
      <geometry>
        <cylinder length="0.03033333" radius="0.043"/>
      </geometry>
      <origin rpy="3.14159 -0.0 3.14159" xyz="0.046000000000747575 2.817227828830503e-07 -0.15671666659962621"/>
    </collision>
    <collision>
      <geometry>
        <cylinder length="0.03033333" radius="0.042"/>
      </geometry>
      <origin rpy="3.14159 -0.0 3.14159" xyz="0.04600000000096117 3.6221500679137236e-07 -0.18704999999951943"/>
    </collision>
    <collision>
      <geometry>
        <cylinder length="0.03033333" radius="0.041"/>
      </geometry>
      <origin rpy="3.14159 -0.0 3.14159" xyz="0.04600000000117476 4.427071420697953e-07 -0.21738329999941264"/>
    </collision>
  </link>

  <joint name="bravo_axis_e" type="revolute">
    <dynamics damping="10.0" friction="0.0"/>
    <limit effort="500.0" lower="0.0" upper="3.14" velocity="3.0"/>
    <parent link="bravo_1013_joint_link"/>
    <child link="bravo_1026_0_joint_link"/>
    <axis xyz=" 0. 0. 1."/>
    <origin rpy="0 0 3.14159" xyz="0.0040000000018364235 -0.29034 0"/> <!-- Old: rpy="3.14159 -0.0 3.14159" xyz="0.0040000000018364235 7.477816037645589e-07 -0.29034999999915573"/>_____________________________________-->
  </joint>

  <link name="bravo_1026_0_joint_link">
    <inertial>
      <origin rpy="0.0 -0.0 0.0" xyz="0.018 0.006 -0.117"/>  <!-- Old: rpy="0.0 -0.0 0.0" xyz="0.017 -0.026 -0.002"_____________________________________-->
      <mass value="1.14"/>
      <inertia ixx="0.021231999999999997" ixy="0.00033" ixz="-0.003738" iyy="0.022251999999999997" iyz="-0.0012779999999999998" izz="0.002054"/>
    </inertial>
    <visual>
      <geometry>
        <mesh filename="C:/Users/marcu/OneDrive/Documents/GitHub/onr_compliance_julia/meshes/RS2-1026_0_end.obj"/>
      </geometry>
      <material name="bravo_black"/>
      <origin rpy="0.0 -0.0 0.0" xyz="0.0 0.0 0.0"/>
    </visual>
    <collision>
      <geometry>
        <cylinder length="0.08" radius="0.0408"/>
      </geometry>
      <origin rpy="0.0 0.0 0.0" xyz="0.0408 0.0 -0.05385"/>
    </collision>
  </link>

  <!-- Changed bravo_axis_d to fixed -->
  <joint name="bravo_axis_d" type="fixed">
    <dynamics damping="10.0" friction="0.0"/>
    <limit effort="500.0" lower="0.0" upper="6.2" velocity="3.0"/>
    <parent link="bravo_1026_0_joint_link"/>
    <child link="bravo_1026_1_joint_link"/>
    <axis xyz=" 0.  0. -1."/>
    <origin rpy="3.14159 0.1 0.0" xyz="0.0408 -0.09434999999999824 0.001"/> <!-- Old: rpy="3.14159 -0.0 0.0" xyz="0.0408 -1.326794896676365e-09 -0.09434999999999824"/>____________________SEEMS TO BE PART OF THE PROBLEM OF MISSALIGNMENT__-->
  </joint>

  <link name="bravo_1026_1_joint_link">
    <inertial>
      <mass value="1.03"/>
      <origin xyz="0.020 -0.024 0.001"/>
      <inertia ixx="0.00243" ixy="-0.001144" ixz="-3.9999999999999996e-05" iyy="0.002026" iyz="1.1e-05" izz="0.00333"/>
    </inertial>
    <visual>
      <geometry>
        <mesh filename="C:/Users/marcu/OneDrive/Documents/GitHub/onr_compliance_julia/meshes/RS2-1026_1_end.obj"/>
      </geometry>
      <material name="bravo_black"/>
      <origin rpy="0.0 3.14159 0" xyz="0.0 0.0 0.0056"/> <!-- Old: rpy="0.0 0.0 3.14159" xyz="0.0 0.0 0.0"/>_________________________________________________________________-->
    </visual>
    <visual>
      <geometry>
        <mesh filename="C:/Users/marcu/OneDrive/Documents/GitHub/onr_compliance_julia/meshes/RS2-1023_0_base.obj"/>
      </geometry>
      <material name="bravo_black"/>
      <origin rpy="0.0 3.14159 0.0" xyz="0.0 0.0 0.0056"/> <!-- Old: rpy="0.0 -0.0 3.14159" xyz="0.0 0.0 0.0056"/>___________________________________________________________-->
    </visual>
    <collision>
      <geometry>
        <cylinder length="0.0056" radius="0.0408"/>
      </geometry>
      <origin rpy="0.0 0.0 3.14159" xyz="0.0 0.0 0.0028"/>
    </collision>
    <collision>
      <geometry>
        <cylinder length="0.03" radius="0.0408"/>
      </geometry>
      <origin rpy="0.0 -0.0 3.14159" xyz="0.0 0.0 0.0206"/>
    </collision>
    <collision>
      <geometry>
        <cylinder length="0.0816" radius="0.0408"/>
      </geometry>
      <origin rpy="1.5707 -0.0 3.14159" xyz="-0.040799999999856354 1.082664635687914e-07 0.0634"/>
    </collision>
  </link>

  <joint name="bravo_axis_c" type="revolute">
    <dynamics damping="10.0" friction="0.0"/>
    <limit effort="500.0" lower="0.0" upper="3.2" velocity="3.0"/>
    <parent link="bravo_1026_1_joint_link"/>
    <child link="bravo_1023_0_joint_link"/>
    <axis xyz=" 0. 0. 1."/>
    <origin rpy="0.0 3.14159 0" xyz="-0.041999999999852135 0.058 0.005"/> <!-- Old: rpy="0.0 -0.0 3.14159" xyz="-0.041999999999852135 1.1145077132081467e-07 0.0634"/>______________________-->
  </joint>

  <link name="bravo_1023_0_joint_link">
    <inertial>
      <origin rpy="0.0 -0.0 0.0" xyz="0.0 0.003 -0.098"/>  <!-- Old: rpy="0.0 -0.0 0.0" xyz="0.0 0.003 -0.098"/>______________________-->
      <mass value="0.333"/>
      <inertia ixx="0.003709" ixy="-2e-06" ixz="-4e-06" iyy="0.003734" iyz="0.0" izz="7.9e-05"/>
    </inertial>
    <visual>
      <geometry>
        <mesh filename="C:/Users/marcu/OneDrive/Documents/GitHub/onr_compliance_julia/meshes/RS2-1023_0_end.obj"/>
      </geometry>
      <material name="bravo_black"/>
      <origin rpy="0.0 -0.0 0.0" xyz="0.0 0.0 0.0"/>
    </visual>
    <collision>
      <geometry>
        <cylinder length="0.08" radius="0.0408"/>
      </geometry>
      <origin rpy="0.0 0.0 0.0" xyz="0.0408 0.0 -0.05385"/>
    </collision>
  </link>

  <!-- Changed bravo_axis_b to fixed -->
  <joint name="bravo_axis_b" type="fixed">
    <dynamics damping="10.0" friction="0.0"/>
    <limit effort="500.0" lower="0.0" upper="6.2" velocity="3.0"/>
    <parent link="bravo_1023_0_joint_link"/>
    <child link="bravo_1023_1_joint_link"/>
    <axis xyz=" 0.  0. -1."/>
    <origin rpy="3.14159 -0.0 0" xyz="0.0408 -0.09434999999999824 0"/> <!-- Old: rpy="3.14159 -0.0 0.6" xyz="0.0408 -1.326794896676365e-09 -0.09434999999999824"/>____________________________-->
  </joint>

  <link name="bravo_1023_1_joint_link">
    <inertial>
      <origin xyz="0.0 0.003 -0.098"/>
      <mass value="1.04"/>
      <inertia ixx="0.022359" ixy="1e-06" ixz="-1.8999999999999998e-05" iyy="0.022362999999999997" iyz="1.4999999999999999e-05" izz="0.000936"/>
    </inertial>
    <visual>
      <geometry>
        <mesh filename="C:/Users/marcu/OneDrive/Documents/GitHub/onr_compliance_julia/meshes/RS2-1023_1_end.obj"/>
      </geometry>
      <material name="bravo_black"/>
      <origin rpy="0.0 -0.0 0.0" xyz="0.0 0.0 0.0"/>
    </visual>
    <visual>
      <geometry>
        <mesh filename="C:/Users/marcu/OneDrive/Documents/GitHub/onr_compliance_julia/meshes/RS2-1028.obj"/>
      </geometry>
      <material name="bravo_black"/>
      <origin rpy="0.0 -0.0 0.0" xyz="0.0 0.0056 0.0"/> <!-- Old: rpy="0.0 -0.0 0.0" xyz="0.0 0.0 0.0056"/>_______________________________________________________________________-->
    </visual>
    <visual>
      <geometry>
        <mesh filename="C:/Users/marcu/OneDrive/Documents/GitHub/onr_compliance_julia/meshes/end_effectors/RS2-257.obj"/>
      </geometry>
      <material name="bravo_finger_jaws_black"/>
      <origin rpy="3.14159 0 1.57" xyz="0.0 0.1256 0"/> <!-- Old: rpy="-1.5707 -1.5706999999997038 0.0" xyz="0.0 0.0 0.1256"/>____________________________________________________-->
    </visual>
    <collision>
      <geometry>
        <cylinder length="0.0056" radius="0.0408"/>
      </geometry>
      <origin rpy="0.0 0.0 0.0" xyz="0.0 0.0 0.0028"/>
    </collision>
    <collision>
      <geometry>
        <cylinder length="0.12" radius="0.0408"/>
      </geometry>
      <origin rpy="0.0 -0.0 0.0" xyz="0.0 0.0 0.06559999999999999"/>
    </collision>
    <collision>
      <geometry>
        <cylinder length="0.02" radius="0.05"/>
      </geometry>
      <origin rpy="-9.632679489654805e-05 -9.631751559834678e-05 -1.5706999907215955" xyz="9.632679474766714e-07 0.0 0.13559999995360572"/>
    </collision>
  </link>

  <!-- <joint name="bravo_axis_a" type="fixed">
    <dynamics damping="10.0" friction="0.0"/>
    <limit effort="1000.0" lower="0.0" upper="0.035" velocity="10.0"/>
    <parent link="bravo_1023_1_joint_link"/>
    <child link="bravo_push_rod"/>
    <axis xyz="0. 0. 1."/>
    <origin rpy="-1.5707 -1.5706999999997038 0.0" xyz="-8.669411487068951e-07 0.008999999958245167 0.12560000008350966"/>
  </joint>

  <link name="bravo_push_rod">
    <inertial>
      <origin rpy="0.0 -0.0 0.0" xyz="0.0 0.0 0.0"/>
      <mass value="0.1"/>
      <inertia ixx="0.0001" ixy="0.0" ixz="0.0" iyy="0.0001" iyz="0.0" izz="0.0001"/>
    </inertial>
  </link> -->

  <joint name="bravo_finger_jaws_rs2_300_joint" type="fixed">
    <!-- Changed joint type to "fixed" to eliminate looping through another dimension -->
    <limit effort="400.0" lower="0.0" upper="1.0" velocity="3.0"/>
    <mimic joint="bravo_axis_a" multiplier="18.0" offset="0.0"/>
    <parent link="bravo_1023_1_joint_link"/>
    <child link="bravo_finger_jaws_rs2_300_link"/>
    <axis xyz=" 0.  0. -1."/>
    <origin rpy="0 3.14159 -1.5707" xyz="0 0.13529682117078565 -0.033"/> <!-- Old: rpy="-1.5707 -1.5706999999997038 0.0" xyz="-0.032999065323888854 -3.178784226673016e-06 0.1353031787392095"/>-->
      <!-- Subtracted 0.265 to the y origin rotation to eliminate finger collision -->
  </joint>

  <joint name="bravo_finger_jaws_rs2_301_joint" type="fixed">
    <!-- Changed joint type to "fixed" to eliminate looping through another dimension -->
    <limit effort="400.0" lower="0.0" upper="1.0" velocity="3.0"/>
    <mimic joint="bravo_finger_jaws_rs2_300_joint" multiplier="1.0" offset="0.0"/>
    <parent link="bravo_1023_1_joint_link"/>
    <child link="bravo_finger_jaws_rs2_301_link"/>
    <axis xyz="0. 0. 1."/>
    <origin rpy="0 3.14159 -1.5707" xyz="0 0.13529682117078565 0.033"/> <!-- Old: rpy="-1.5707 -1.5706999999997038 0.0" xyz="0.03300093406370696 3.178784226673016e-06 0.13529682117078565"/>-->
    <!-- Added 0.265 to the y origin rotation to eliminate finger collision -->
  </joint>

  <link name="bravo_finger_jaws_rs2_300_link">
    <inertial>
      <origin rpy="0.0 -0.0 0.0" xyz="0.05 0.0 0.0"/>
      <mass value="0.24"/>
      <inertia ixx="0.000244" ixy="-1.2e-05" ixz="0.0" iyy="0.00113" iyz="1e-06" izz="0.001178"/>
    </inertial>
    <visual>
      <geometry>
        <mesh filename="C:/Users/marcu/OneDrive/Documents/GitHub/onr_compliance_julia/meshes/end_effectors/RS2-300.obj"/>
      </geometry>
      <material name="bravo_finger_jaws_black"/>
      <origin rpy="0.0 -0.0 0.0" xyz="0.0 0.0 0.0"/>
    </visual>
    <collision>
      <geometry>
        <mesh filename="C:/Users/marcu/OneDrive/Documents/GitHub/onr_compliance_julia/meshes/end_effectors/RS2-300.obj"/>
      </geometry>
      <origin rpy="0.0 -0.0 0.0" xyz="0.0 0.0 0.0"/>
    </collision>
  </link>

  <link name="bravo_finger_jaws_rs2_301_link">
    <inertial>
      <origin rpy="0.0 -0.0 0.0" xyz="0.05 0.0 0.0"/>
      <mass value="0.24"/>
      <inertia ixx="0.000244" ixy="-1.2e-05" ixz="0.0" iyy="0.00113" iyz="1e-06" izz="0.001178"/>
    </inertial>
    <visual>
      <geometry>
        <mesh filename="C:/Users/marcu/OneDrive/Documents/GitHub/onr_compliance_julia/meshes/end_effectors/RS2-301.obj"/>
      </geometry>
      <material name="bravo_finger_jaws_black"/>
      <origin rpy="0.0 -0.0 0.0" xyz="0.0 0.0 0.0"/>
    </visual>
    <collision>
      <geometry>
        <mesh filename="C:/Users/marcu/OneDrive/Documents/GitHub/onr_compliance_julia/meshes/end_effectors/RS2-301.obj"/>
      </geometry>
      <origin rpy="0.0 -0.0 0.0" xyz="0.0 0.0 0.0"/>
    </collision>
  </link>

  <link name="ee_link"/>

  <joint name="ee_link_joint" type="fixed">
    <parent link="bravo_1023_1_joint_link"/>
    <child link="ee_link"/>
    <origin rpy="0 0 -1.5707" xyz="0 0 0.120"/>
  </joint>

</robot>